Workbook

Sheet Start here
A1: Radiative Transfer Lab (spreadsheet edition)
A2: Companion to the two courses 'Radiative Transfer' (RT1-RT6) and 'Stellar Atmospheres' (SA1-SA5). One sheet per experiment, labelled with its lecture.
A4: How to use
A5: Yellow cell, blue text | B5: INPUT: type a new value here. Everything else on the sheet updates automatically.
A6: Light-blue cell | B6: RESULT: a formula computed from the inputs (do not type over it).
A7: Tables and charts | B7: Computed from the inputs with formulas; the charts redraw when you change an input.
A8: Cell comments | B8: Hover over an input cell to see what it means and a sensible range.
A9: Example values | B9: Each sheet opens with realistic example values (e.g. the Sun: T_eff = 5772 K).
A11: Sheets
A12: RT1 Optical depth | B12: Beam attenuation, optical depth, magnitudes of extinction
A13: RT1 Intensity | B13: Flux falls as 1/d^2, solid angle too: intensity is conserved
A14: RT2 Planck | B14: Black-body spectrum, Wien peak, Stefan-Boltzmann, RJ and Wien limits
A15: RT2 Random walk | B15: Mean free path, photon diffusion time, thermalisation depth
A16: RT3 Slab & MIT star | B16: Slab solution; MIT two-layer star with Balmer + Paschen lines; thermal inversion
A17: SA1 Saha-Boltzmann | B17: Hydrogen ionisation and n=2 population; why Balmer lines peak in A stars
A18: RT4 Eddington-Barbier | B18: Emergent intensity, limb darkening, Eddington-Barbier error
A19: RT4 Scattering | B19: S = eps B + (1-eps) J: Eddington solution, sqrt(eps) law; Rosseland mean calculator
A20: SA4 Gray atmosphere | B20: Exact gray LTE model: T(tau), limb darkening at any wavelength, emergent spectrum, pressure
A21: SA4 Lines | B21: Milne-Eddington LTE line profile and curve of growth
A22: Constants | B22: Physical constants used by all formulas (named cells)
A23: Data | B23: Fixed mathematical tables from scripts/lte_solvers.py (Hopf q, E2, H-function, exact scattering)
A25: An interactive web version with sliders (same physics) is in app/index.html of the course repository.

Sheet RT1 Optical depth
A1: Lecture RT1 - How much light gets through a slab of gas?
A2: Absorption removes a fixed fraction of the beam per unit length. Optical depth counts mean free paths.
A3: Equation: I(s) = I(0) exp(-tau), tau = alpha * s, A = 1.086 tau [mag]
A5: Inputs
A6: Absorption coefficient alpha | B6: 0.5 | C6: per km
A7: Path length L | B7: 4 | C7: km
A9: Results
A10: Optical depth tau = alpha L | B10: =$B$6*$B$7 -> 2
A11: Transmitted fraction exp(-tau) | B11: =EXP(-$B$10) -> 0.13533528
A12: Extinction A = 2.5 log10(e^tau) | B12: =1.0857*$B$10 -> 2.1714 | C12: mag
A13: Mean free path 1/alpha | B13: =1/$B$6 -> 2 | C13: km
A14: Regime | B14: =IF($B$10<0.3,"optically thin",IF($B$10<3,"intermediate (tau ~ 1)","optically thick")) -> intermediate (tau ~ 1)
E16: s [km] | F16: I(s)/I(0)
E17: =$B$7*1.5*0/40 -> 0 | F17: =EXP(-$B$6*E17) -> 1
E18: =$B$7*1.5*1/40 -> 0.15 | F18: =EXP(-$B$6*E18) -> 0.92774349
E19: =$B$7*1.5*2/40 -> 0.3 | F19: =EXP(-$B$6*E19) -> 0.86070798
E20: =$B$7*1.5*3/40 -> 0.45 | F20: =EXP(-$B$6*E20) -> 0.79851622
E21: =$B$7*1.5*4/40 -> 0.6 | F21: =EXP(-$B$6*E21) -> 0.74081822
E22: =$B$7*1.5*5/40 -> 0.75 | F22: =EXP(-$B$6*E22) -> 0.68728928
E23: =$B$7*1.5*6/40 -> 0.9 | F23: =EXP(-$B$6*E23) -> 0.63762815
E24: =$B$7*1.5*7/40 -> 1.05 | F24: =EXP(-$B$6*E24) -> 0.59155536
E25: =$B$7*1.5*8/40 -> 1.2 | F25: =EXP(-$B$6*E25) -> 0.54881164
E26: =$B$7*1.5*9/40 -> 1.35 | F26: =EXP(-$B$6*E26) -> 0.50915642
E27: =$B$7*1.5*10/40 -> 1.5 | F27: =EXP(-$B$6*E27) -> 0.47236655
E28: =$B$7*1.5*11/40 -> 1.65 | F28: =EXP(-$B$6*E28) -> 0.43823499
E29: =$B$7*1.5*12/40 -> 1.8 | F29: =EXP(-$B$6*E29) -> 0.40656966
E30: =$B$7*1.5*13/40 -> 1.95 | F30: =EXP(-$B$6*E30) -> 0.37719235
E31: =$B$7*1.5*14/40 -> 2.1 | F31: =EXP(-$B$6*E31) -> 0.34993775
E32: =$B$7*1.5*15/40 -> 2.25 | F32: =EXP(-$B$6*E32) -> 0.32465247
E33: =$B$7*1.5*16/40 -> 2.4 | F33: =EXP(-$B$6*E33) -> 0.30119421
E34: =$B$7*1.5*17/40 -> 2.55 | F34: =EXP(-$B$6*E34) -> 0.27943097
E35: =$B$7*1.5*18/40 -> 2.7 | F35: =EXP(-$B$6*E35) -> 0.25924026
E36: =$B$7*1.5*19/40 -> 2.85 | F36: =EXP(-$B$6*E36) -> 0.24050846
E37: =$B$7*1.5*20/40 -> 3 | F37: =EXP(-$B$6*E37) -> 0.22313016
E38: =$B$7*1.5*21/40 -> 3.15 | F38: =EXP(-$B$6*E38) -> 0.20700755
E39: =$B$7*1.5*22/40 -> 3.3 | F39: =EXP(-$B$6*E39) -> 0.19204991
E40: =$B$7*1.5*23/40 -> 3.45 | F40: =EXP(-$B$6*E40) -> 0.17817305
E41: =$B$7*1.5*24/40 -> 3.6 | F41: =EXP(-$B$6*E41) -> 0.16529889
E42: =$B$7*1.5*25/40 -> 3.75 | F42: =EXP(-$B$6*E42) -> 0.15335497
E43: =$B$7*1.5*26/40 -> 3.9 | F43: =EXP(-$B$6*E43) -> 0.14227407
...

Sheet RT1 Intensity
A1: Lecture RT1 - Why a star looks equally bright per square arcsecond from any distance
A2: Flux falls as 1/d^2, but the solid angle of the star falls in exactly the same way: their ratio, the intensity, is constant.
A3: Equation: F(d) = sigma T^4 (R/d)^2, Omega = pi (R/d)^2, I = F/Omega = sigma T^4 / pi
A5: Inputs
A6: Effective temperature T_eff | B6: 5772 | C6: K
A7: Stellar radius R | B7: 1 | C7: R_sun
A8: Distance d | B8: 1 | C8: AU
A10: Results
A11: Surface flux sigma T^4 | B11: =sigSB*$B$6^4 -> 62938588 | C11: W m^-2
A12: (R/d)^2 | B12: =($B$7*Rsun/($B$8*AU))^2 -> 2.1626846e-05
A13: Flux received F | B13: =$B$11*$B$12 -> 1361.1631 | C13: W m^-2
A14: Solid angle Omega | B14: =PI()*$B$12 -> 6.794274e-05 | C14: sr
A15: Intensity I = F / Omega | B15: =B13/B14 -> 20033975 | C15: W m^-2 sr^-1
A16: Same as sigma T^4 / pi ? | B16: =$B$11/PI() -> 20033975 | C16: W m^-2 sr^-1
A17: Angular diameter | B17: =2*ASIN(SQRT($B$12))*206264.806 -> 1918.4624 | C17: arcsec
A18: Luminosity | B18: =4*PI()*($B$7*Rsun)^2*$B$11/Lsun -> 0.99999755 | C18: L_sun
E20: d [AU] | F20: F / F_surface | G20: Omega / pi | H20: I / I_surface
E21: 0.01 | F21: =($B$7*Rsun/(E21*AU))^2 -> 0.21626846 | G21: =F21 -> 0.21626846 | H21: =1 -> 1
E22: 0.017782794 | F22: =($B$7*Rsun/(E22*AU))^2 -> 0.068390091 | G22: =F22 -> 0.068390091 | H22: =1 -> 1
E23: 0.031622777 | F23: =($B$7*Rsun/(E23*AU))^2 -> 0.021626846 | G23: =F23 -> 0.021626846 | H23: =1 -> 1
E24: 0.056234133 | F24: =($B$7*Rsun/(E24*AU))^2 -> 0.0068390091 | G24: =F24 -> 0.0068390091 | H24: =1 -> 1
E25: 0.1 | F25: =($B$7*Rsun/(E25*AU))^2 -> 0.0021626846 | G25: =F25 -> 0.0021626846 | H25: =1 -> 1
E26: 0.17782794 | F26: =($B$7*Rsun/(E26*AU))^2 -> 0.00068390091 | G26: =F26 -> 0.00068390091 | H26: =1 -> 1
E27: 0.31622777 | F27: =($B$7*Rsun/(E27*AU))^2 -> 0.00021626846 | G27: =F27 -> 0.00021626846 | H27: =1 -> 1
E28: 0.56234133 | F28: =($B$7*Rsun/(E28*AU))^2 -> 6.8390091e-05 | G28: =F28 -> 6.8390091e-05 | H28: =1 -> 1
E29: 1 | F29: =($B$7*Rsun/(E29*AU))^2 -> 2.1626846e-05 | G29: =F29 -> 2.1626846e-05 | H29: =1 -> 1
E30: 1.7782794 | F30: =($B$7*Rsun/(E30*AU))^2 -> 6.8390091e-06 | G30: =F30 -> 6.8390091e-06 | H30: =1 -> 1
E31: 3.1622777 | F31: =($B$7*Rsun/(E31*AU))^2 -> 2.1626846e-06 | G31: =F31 -> 2.1626846e-06 | H31: =1 -> 1
E32: 5.6234133 | F32: =($B$7*Rsun/(E32*AU))^2 -> 6.8390091e-07 | G32: =F32 -> 6.8390091e-07 | H32: =1 -> 1
... E53: 1000000 | F53: =($B$7*Rsun/(E53*AU))^2 -> 2.1626846e-17 | G53: =F53 -> 2.1626846e-17 | H53: =1 -> 1

Sheet RT2 Planck
A1: Lecture RT2 - How a black body changes with temperature
A2: Raise T: the peak moves to shorter wavelengths (Wien) and the total flux grows as T^4 (Stefan-Boltzmann).
A3: Equation: B_lambda(T) = 2hc^2/lambda^5 / (exp(hc/(lambda k T)) - 1); lambda_max T = 2.898e-3 m K; F = sigma T^4
A5: Inputs
A6: Temperature T | B6: 5772 | C6: K
A7: Comparison temperature | B7: 5772 | C7: K
A9: Results
A10: Peak wavelength lambda_max | B10: =0.002897771955/$B$6*1000000000 -> 502.03949 | C10: nm
A11: Peak frequency nu_max = 5.879e10 T | B11: =58790000000*$B$6 -> 339335880000000 | C11: Hz
A12: Surface flux sigma T^4 | B12: =sigSB*$B$6^4 -> 62938588 | C12: W m^-2
A13: Flux relative to the Sun | B13: =($B$6/5772)^4 -> 1
A14: B_lambda at 500 nm | B14: =2*hP*cL^2/(0.0000005)^5/(EXP(hP*cL/(0.0000005*kB*$B$6))-1) -> 2.6238541e+13 | C14: W m^-3 sr^-1
A15: x = hc/(lambda k T) at 500 nm | B15: =hP*cL/(0.0000005*kB*$B$6) -> 4.9853669
E17: lambda [nm] | F17: B_lambda(T) | G17: B_lambda(T2) | H17: Rayleigh-Jeans | I17: Wien
E18: 100 | F18: =2*hP*cL^2/(E18*0.000000001)^5/(EXP(hP*cL/(E18*0.000000001*kB*$B$6))-1) -> 1.7796755e+08 | G18: =2*hP*cL^2/(E18*0.000000001)^5/(EXP(hP*cL/(E18*0.000000001*kB*$B$7))-1) -> 1.7796755e+08 | H18: =2*cL*kB*$B$6/(E18*0.000000001)^4 -> 4.7781558e+17 | I18: =2*hP*cL^2/(E18*0.000000001)^5*EXP(-hP*cL/(E18*0.000000001*kB*$B$6)) -> 1.7796755e+08
E19: 106.86 | F19: =2*hP*cL^2/(E19*0.000000001)^5/(EXP(hP*cL/(E19*0.000000001*kB*$B$6))-1) -> 6.3274089e+08 | G19: =2*hP*cL^2/(E19*0.000000001)^5/(EXP(hP*cL/(E19*0.000000001*kB*$B$7))-1) -> 6.3274089e+08 | H19: =2*cL*kB*$B$6/(E19*0.000000001)^4 -> 3.6643726e+17 | I19: =2*hP*cL^2/(E19*0.000000001)^5*EXP(-hP*cL/(E19*0.000000001*kB*$B$6)) -> 6.3274089e+08
E20: 114.18 | F20: =2*hP*cL^2/(E20*0.000000001)^5/(EXP(hP*cL/(E20*0.000000001*kB*$B$6))-1) -> 2.0268373e+09 | G20: =2*hP*cL^2/(E20*0.000000001)^5/(EXP(hP*cL/(E20*0.000000001*kB*$B$7))-1) -> 2.0268373e+09 | H20: =2*cL*kB*$B$6/(E20*0.000000001)^4 -> 2.8112544e+17 | I20: =2*hP*cL^2/(E20*0.000000001)^5*EXP(-hP*cL/(E20*0.000000001*kB*$B$6)) -> 2.0268373e+09
E21: 122.01 | F21: =2*hP*cL^2/(E21*0.000000001)^5/(EXP(hP*cL/(E21*0.000000001*kB*$B$6))-1) -> 5.9053539e+09 | G21: =2*hP*cL^2/(E21*0.000000001)^5/(EXP(hP*cL/(E21*0.000000001*kB*$B$7))-1) -> 5.9053539e+09 | H21: =2*cL*kB*$B$6/(E21*0.000000001)^4 -> 2.1561481e+17 | I21: =2*hP*cL^2/(E21*0.000000001)^5*EXP(-hP*cL/(E21*0.000000001*kB*$B$6)) -> 5.9053539e+09
E22: 130.37 | F22: =2*hP*cL^2/(E22*0.000000001)^5/(EXP(hP*cL/(E22*0.000000001*kB*$B$6))-1) -> 1.5714426e+10 | G22: =2*hP*cL^2/(E22*0.000000001)^5/(EXP(hP*cL/(E22*0.000000001*kB*$B$7))-1) -> 1.5714426e+10 | H22: =2*cL*kB*$B$6/(E22*0.000000001)^4 -> 1.6540538e+17 | I22: =2*hP*cL^2/(E22*0.000000001)^5*EXP(-hP*cL/(E22*0.000000001*kB*$B$6)) -> 1.5714426e+10
E23: 139.31 | F23: =2*hP*cL^2/(E23*0.000000001)^5/(EXP(hP*cL/(E23*0.000000001*kB*$B$6))-1) -> 3.8472896e+10 | G23: =2*hP*cL^2/(E23*0.000000001)^5/(EXP(hP*cL/(E23*0.000000001*kB*$B$7))-1) -> 3.8472896e+10 | H23: =2*cL*kB*$B$6/(E23*0.000000001)^4 -> 1.2686188e+17 | I23: =2*hP*cL^2/(E23*0.000000001)^5*EXP(-hP*cL/(E23*0.000000001*kB*$B$6)) -> 3.8472895e+10
E24: 148.86 | F24: =2*hP*cL^2/(E24*0.000000001)^5/(EXP(hP*cL/(E24*0.000000001*kB*$B$6))-1) -> 8.7038212e+10 | G24: =2*hP*cL^2/(E24*0.000000001)^5/(EXP(hP*cL/(E24*0.000000001*kB*$B$7))-1) -> 8.7038212e+10 | H24: =2*cL*kB*$B$6/(E24*0.000000001)^4 -> 9.7307932e+16 | I24: =2*hP*cL^2/(E24*0.000000001)^5*EXP(-hP*cL/(E24*0.000000001*kB*$B$6)) -> 8.7038207e+10
E25: 159.06 | F25: =2*hP*cL^2/(E25*0.000000001)^5/(EXP(hP*cL/(E25*0.000000001*kB*$B$6))-1) -> 1.8287143e+11 | G25: =2*hP*cL^2/(E25*0.000000001)^5/(EXP(hP*cL/(E25*0.000000001*kB*$B$7))-1) -> 1.8287143e+11 | H25: =2*cL*kB*$B$6/(E25*0.000000001)^4 -> 7.4647693e+16 | I25: =2*hP*cL^2/(E25*0.000000001)^5*EXP(-hP*cL/(E25*0.000000001*kB*$B$6)) -> 1.8287141e+11
E26: 169.97 | F26: =2*hP*cL^2/(E26*0.000000001)^5/(EXP(hP*cL/(E26*0.000000001*kB*$B$6))-1) -> 3.5888075e+11 | G26: =2*hP*cL^2/(E26*0.000000001)^5/(EXP(hP*cL/(E26*0.000000001*kB*$B$7))-1) -> 3.5888075e+11 | H26: =2*cL*kB*$B$6/(E26*0.000000001)^4 -> 5.7249435e+16 | I26: =2*hP*cL^2/(E26*0.000000001)^5*EXP(-hP*cL/(E26*0.000000001*kB*$B$6)) -> 3.588806e+11
E27: 181.62 | F27: =2*hP*cL^2/(E27*0.000000001)^5/(EXP(hP*cL/(E27*0.000000001*kB*$B$6))-1) -> 6.5999386e+11 | G27: =2*hP*cL^2/(E27*0.000000001)^5/(EXP(hP*cL/(E27*0.000000001*kB*$B$7))-1) -> 6.5999386e+11 | H27: =2*cL*kB*$B$6/(E27*0.000000001)^4 -> 4.3914265e+16 | I27: =2*hP*cL^2/(E27*0.000000001)^5*EXP(-hP*cL/(E27*0.000000001*kB*$B$6)) -> 6.5999314e+11
E28: 194.07 | F28: =2*hP*cL^2/(E28*0.000000001)^5/(EXP(hP*cL/(E28*0.000000001*kB*$B$6))-1) -> 1.1427468e+12 | G28: =2*hP*cL^2/(E28*0.000000001)^5/(EXP(hP*cL/(E28*0.000000001*kB*$B$7))-1) -> 1.1427468e+12 | H28: =2*cL*kB*$B$6/(E28*0.000000001)^4 -> 3.3684234e+16 | I28: =2*hP*cL^2/(E28*0.000000001)^5*EXP(-hP*cL/(E28*0.000000001*kB*$B$6)) -> 1.1427438e+12
E29: 207.38 | F29: =2*hP*cL^2/(E29*0.000000001)^5/(EXP(hP*cL/(E29*0.000000001*kB*$B$6))-1) -> 1.8703662e+12 | G29: =2*hP*cL^2/(E29*0.000000001)^5/(EXP(hP*cL/(E29*0.000000001*kB*$B$7))-1) -> 1.8703662e+12 | H29: =2*cL*kB*$B$6/(E29*0.000000001)^4 -> 2.5834069e+16 | I29: =2*hP*cL^2/(E29*0.000000001)^5*EXP(-hP*cL/(E29*0.000000001*kB*$B$6)) -> 1.8703549e+12
... E77: 5000 | F77: =2*hP*cL^2/(E77*0.000000001)^5/(EXP(hP*cL/(E77*0.000000001*kB*$B$6))-1) -> 5.8970694e+10 | G77: =2*hP*cL^2/(E77*0.000000001)^5/(EXP(hP*cL/(E77*0.000000001*kB*$B$7))-1) -> 5.8970694e+10 | H77: =2*cL*kB*$B$6/(E77*0.000000001)^4 -> 7.6450492e+10 | I77: =2*hP*cL^2/(E77*0.000000001)^5*EXP(-hP*cL/(E77*0.000000001*kB*$B$6)) -> 2.3150783e+10

Sheet RT2 Random walk
A1: Lecture RT2 - How long does light take to leave a star?
A2: A scattered photon random-walks: after N steps of length l it is only sqrt(N) l away, so escaping from optical depth tau takes N ~ tau^2 steps.
A3: Equation: l = 1/(n sigma), tau = R/l, N = tau^2, t = R^2/(l c), thermalisation depth ~ 1/sqrt(eps)
A5: Inputs (default: uniform Sun, Thomson scattering)
A6: Mass | B6: 1 | C6: M_sun
A7: Radius | B7: 1 | C7: R_sun
A8: Hydrogen mass fraction X | B8: 0.7
A9: Destruction probability eps | B9: 0.001
A11: Results
A12: Mean density | B12: =$B$6*1.989E+030/(4/3*PI()*($B$7*Rsun)^3) -> 1410.1982 | C12: kg m^-3
A13: Electron density n_e = rho/(mu_e m_H) | B13: =$B$12/((2/(1+$B$8))*mH) -> 7.1626441e+29 | C13: m^-3
A14: Mean free path l = 1/(n_e sigma_T) | B14: =1/($B$13*sigT) -> 0.020986714 | C14: m
A15: Optical radius tau = R/l | B15: =$B$7*Rsun/$B$14 -> 3.3149544e+10
A16: Number of scatterings N = tau^2 | B16: =$B$15^2 -> 1.0988923e+21
A17: Diffusion time R^2/(l c) | B17: =($B$7*Rsun)^2/($B$14*cL)/yr -> 2437.6699 | C17: years
A18: Light-crossing time R/c | B18: =$B$7*Rsun/cL -> 2.3206054 | C18: s
A19: Thermalisation depth 1/sqrt(eps) | B19: =1/SQRT($B$9) -> 31.622777
A20: Scatterings before destruction 1/eps | B20: =1/$B$9 -> 1000
E22: cloud tau | F22: N = tau^2 | G22: escape chance ~ exp(-tau sqrt(3 eps))
E23: 1 | F23: =E23^2 -> 1 | G23: =MIN(1,EXP(-E23*SQRT(3*$B$9))) -> 0.94670073
E24: 2 | F24: =E24^2 -> 4 | G24: =MIN(1,EXP(-E24*SQRT(3*$B$9))) -> 0.89624227
E25: 3 | F25: =E25^2 -> 9 | G25: =MIN(1,EXP(-E25*SQRT(3*$B$9))) -> 0.84847321
E26: 4 | F26: =E26^2 -> 16 | G26: =MIN(1,EXP(-E26*SQRT(3*$B$9))) -> 0.80325021
E27: 5 | F27: =E27^2 -> 25 | G27: =MIN(1,EXP(-E27*SQRT(3*$B$9))) -> 0.76043756
E28: 6 | F28: =E28^2 -> 36 | G28: =MIN(1,EXP(-E28*SQRT(3*$B$9))) -> 0.71990679
E29: 7 | F29: =E29^2 -> 49 | G29: =MIN(1,EXP(-E29*SQRT(3*$B$9))) -> 0.68153628
E30: 8 | F30: =E30^2 -> 64 | G30: =MIN(1,EXP(-E30*SQRT(3*$B$9))) -> 0.6452109
E31: 9 | F31: =E31^2 -> 81 | G31: =MIN(1,EXP(-E31*SQRT(3*$B$9))) -> 0.61082163
E32: 10 | F32: =E32^2 -> 100 | G32: =MIN(1,EXP(-E32*SQRT(3*$B$9))) -> 0.57826528
E33: 11 | F33: =E33^2 -> 121 | G33: =MIN(1,EXP(-E33*SQRT(3*$B$9))) -> 0.54744416
E34: 12 | F34: =E34^2 -> 144 | G34: =MIN(1,EXP(-E34*SQRT(3*$B$9))) -> 0.51826579
... E52: 30 | F52: =E52^2 -> 900 | G52: =MIN(1,EXP(-E52*SQRT(3*$B$9))) -> 0.19336655

Sheet RT3 Slab & MIT star
A1: Lecture RT3 - Absorption or emission lines? A slab and the MIT 8.901 two-layer star
A2: The beam relaxes toward the source function. Lines are dark if the gas in front is cooler than the background, bright if hotter.
A3: Equation: I = I0 exp(-tau) + S (1 - exp(-tau)); I = B(T_base) exp(-tau) + B(T_top) (1 - exp(-tau))
A5: Part A - uniform slab | M5: n1 | N5: n2 | O5: lambda0 [nm] (Rydberg) | P5: relative strength
A6: Incoming intensity I(0)/S | B6: 2.2 | M6: 2 | N6: 3 | O6: 656.467 | P6: 1
A7: Slab optical depth tau | B7: 1.5 | M7: 2 | N7: 4 | O7: 486.272 | P7: 0.42188
A8: Emergent I/S | B8: =$B$6*EXP(-$B$7)+(1-EXP(-$B$7)) -> 1.2677562 | M8: 2 | N8: 5 | O8: 434.171 | P8: 0.216
M9: 2 | N9: 6 | O9: 410.292 | P9: 0.125
A10: Part B - MIT two-layer star | M10: 2 | N10: 7 | O10: 397.122 | P10: 0.07872
A11: T_base (thick interior) | B11: 6500 | C11: K | M11: 2 | N11: 8 | O11: 389.018 | P11: 0.05273
A12: T_top (thin upper layer) | B12: 4500 | C12: K | M12: 2 | N12: 9 | O12: 383.65 | P12: 0.03704
A13: Line strength tau0 (H-alpha) | B13: 2 | M13: 2 | N13: 10 | O13: 379.9 | P13: 0.027
A14: Continuum optical depth tau_c | B14: 0.02 | M14: 2 | N14: 11 | O14: 377.172 | P14: 0.02029
A15: Background: 1 = thick base, 0 = dark sky | B15: 1 | M15: 2 | N15: 12 | O15: 375.124 | P15: 0.01562
M16: 2 | N16: 13 | O16: 373.545 | P16: 0.01229
A17: Results at H-alpha (656.47 nm) | M17: 3 | N17: 4 | O17: 1875.62 | P17: 0.6
A18: tau at line centre | B18: =$B$14+$B$13*SUMPRODUCT($P$6:$P$27,EXP(0-((656.47-$O$6:$O$27)/1.2)^2)) -> 2.0199875 | M18: 3 | N18: 5 | O18: 1282.162 | P18: 0.3072
A19: Continuum intensity | B19: =$B$15*(2*hP*cL^2/(0.00000065647)^5/(EXP(hP*cL/(0.00000065647*kB*$B$11))-1))*EXP(-$B$14)+(2*hP*cL^2/(0.00000065647)^5/(EXP(hP*cL/(0.00000065647*kB*$B$12))-1))*(1-EXP(-$B$14)) -> 3.4188094e+13 | C19: W m^-3 sr^-1 | M19: 3 | N19: 6 | O19: 1094.112 | P19: 0.17778
A20: Line-centre intensity | B20: =$B$15*(2*hP*cL^2/(0.00000065647)^5/(EXP(hP*cL/(0.00000065647*kB*$B$11))-1))*EXP(-$B$18)+(2*hP*cL^2/(0.00000065647)^5/(EXP(hP*cL/(0.00000065647*kB*$B$12))-1))*(1-EXP(-$B$18)) -> 11155949625583 | C20: W m^-3 sr^-1 | M20: 3 | N20: 7 | O20: 1005.215 | P20: 0.11195
A21: Line depth 1 - I_line/I_cont | B21: =1-$B$20/$B$19 -> 0.67368905 | C21: (negative = emission) | M21: 3 | N21: 8 | O21: 954.861 | P21: 0.075
A22: Line type | B22: =IF($B$20<$B$19,"absorption line","emission line") -> absorption line | M22: 3 | N22: 9 | O22: 923.157 | P22: 0.05267
M23: 3 | N23: 10 | O23: 901.741 | P23: 0.0384
M24: 3 | N24: 11 | O24: 886.524 | P24: 0.02885
E25: tau | F25: I/S | G25: S | H25: lambda [nm] | I25: tau(lambda) | J25: I [1e12] | K25: B(T_base) x bg [1e12] | L25: B(T_top) [1e12] | M25: 3 | N25: 12 | O25: 875.289 | P25: 0.02222
E26: =6*0/30 -> 0 | F26: =$B$6*EXP(-E26)+(1-EXP(-E26)) -> 2.2 | G26: =1 -> 1 | H26: 360 | I26: =$B$14+$B$13*SUMPRODUCT($P$6:$P$27,EXP(0-((H26-$O$6:$O$27)/1.2)^2)) -> 0.02 | J26: =($B$15*(2*hP*cL^2/(H26*0.000000001)^5/(EXP(hP*cL/(H26*0.000000001*kB*$B$11))-1))*EXP(-I26)+(2*hP*cL^2/(H26*0.000000001)^5/(EXP(hP*cL/(H26*0.000000001*kB*$B$12))-1))*(1-EXP(-I26)))/1000000000000 -> 41.391926 | K26: =$B$15*(2*hP*cL^2/(H26*0.000000001)^5/(EXP(hP*cL/(H26*0.000000001*kB*$B$11))-1))/1000000000000 -> 42.172796 | L26: =(2*hP*cL^2/(H26*0.000000001)^5/(EXP(hP*cL/(H26*0.000000001*kB*$B$12))-1))/1000000000000 -> 2.7375299 | M26: 3 | N26: 13 | O26: 866.742 | P26: 0.01748
E27: =6*1/30 -> 0.2 | F27: =$B$6*EXP(-E27)+(1-EXP(-E27)) -> 1.9824769 | G27: =1 -> 1 | H27: 362 | I27: =$B$14+$B$13*SUMPRODUCT($P$6:$P$27,EXP(0-((H27-$O$6:$O$27)/1.2)^2)) -> 0.02 | J27: =($B$15*(2*hP*cL^2/(H27*0.000000001)^5/(EXP(hP*cL/(H27*0.000000001*kB*$B$11))-1))*EXP(-I27)+(2*hP*cL^2/(H27*0.000000001)^5/(EXP(hP*cL/(H27*0.000000001*kB*$B$12))-1))*(1-EXP(-I27)))/1000000000000 -> 41.65615 | K27: =$B$15*(2*hP*cL^2/(H27*0.000000001)^5/(EXP(hP*cL/(H27*0.000000001*kB*$B$11))-1))/1000000000000 -> 42.441163 | L27: =(2*hP*cL^2/(H27*0.000000001)^5/(EXP(hP*cL/(H27*0.000000001*kB*$B$12))-1))/1000000000000 -> 2.7966724 | M27: 3 | N27: 14 | O27: 860.077 | P27: 0.01399
E28: =6*2/30 -> 0.4 | F28: =$B$6*EXP(-E28)+(1-EXP(-E28)) -> 1.8043841 | G28: =1 -> 1 | H28: 364 | I28: =$B$14+$B$13*SUMPRODUCT($P$6:$P$27,EXP(0-((H28-$O$6:$O$27)/1.2)^2)) -> 0.02 | J28: =($B$15*(2*hP*cL^2/(H28*0.000000001)^5/(EXP(hP*cL/(H28*0.000000001*kB*$B$11))-1))*EXP(-I28)+(2*hP*cL^2/(H28*0.000000001)^5/(EXP(hP*cL/(H28*0.000000001*kB*$B$12))-1))*(1-EXP(-I28)))/1000000000000 -> 41.912885 | K28: =$B$15*(2*hP*cL^2/(H28*0.000000001)^5/(EXP(hP*cL/(H28*0.000000001*kB*$B$11))-1))/1000000000000 -> 42.701887 | L28: =(2*hP*cL^2/(H28*0.000000001)^5/(EXP(hP*cL/(H28*0.000000001*kB*$B$12))-1))/1000000000000 -> 2.855989
E29: =6*3/30 -> 0.6 | F29: =$B$6*EXP(-E29)+(1-EXP(-E29)) -> 1.658574 | G29: =1 -> 1 | H29: 366 | I29: =$B$14+$B$13*SUMPRODUCT($P$6:$P$27,EXP(0-((H29-$O$6:$O$27)/1.2)^2)) -> 0.02 | J29: =($B$15*(2*hP*cL^2/(H29*0.000000001)^5/(EXP(hP*cL/(H29*0.000000001*kB*$B$11))-1))*EXP(-I29)+(2*hP*cL^2/(H29*0.000000001)^5/(EXP(hP*cL/(H29*0.000000001*kB*$B$12))-1))*(1-EXP(-I29)))/1000000000000 -> 42.162161 | K29: =$B$15*(2*hP*cL^2/(H29*0.000000001)^5/(EXP(hP*cL/(H29*0.000000001*kB*$B$11))-1))/1000000000000 -> 42.954997 | L29: =(2*hP*cL^2/(H29*0.000000001)^5/(EXP(hP*cL/(H29*0.000000001*kB*$B$12))-1))/1000000000000 -> 2.9154582
E30: =6*4/30 -> 0.8 | F30: =$B$6*EXP(-E30)+(1-EXP(-E30)) -> 1.5391948 | G30: =1 -> 1 | H30: 368 | I30: =$B$14+$B$13*SUMPRODUCT($P$6:$P$27,EXP(0-((H30-$O$6:$O$27)/1.2)^2)) -> 0.02 | J30: =($B$15*(2*hP*cL^2/(H30*0.000000001)^5/(EXP(hP*cL/(H30*0.000000001*kB*$B$11))-1))*EXP(-I30)+(2*hP*cL^2/(H30*0.000000001)^5/(EXP(hP*cL/(H30*0.000000001*kB*$B$12))-1))*(1-EXP(-I30)))/1000000000000 -> 42.40401 | K30: =$B$15*(2*hP*cL^2/(H30*0.000000001)^5/(EXP(hP*cL/(H30*0.000000001*kB*$B$11))-1))/1000000000000 -> 43.200528 | L30: =(2*hP*cL^2/(H30*0.000000001)^5/(EXP(hP*cL/(H30*0.000000001*kB*$B$12))-1))/1000000000000 -> 2.9750584
E31: =6*5/30 -> 1 | F31: =$B$6*EXP(-E31)+(1-EXP(-E31)) -> 1.4414553 | G31: =1 -> 1 | H31: 370 | I31: =$B$14+$B$13*SUMPRODUCT($P$6:$P$27,EXP(0-((H31-$O$6:$O$27)/1.2)^2)) -> 0.020003986 | J31: =($B$15*(2*hP*cL^2/(H31*0.000000001)^5/(EXP(hP*cL/(H31*0.000000001*kB*$B$11))-1))*EXP(-I31)+(2*hP*cL^2/(H31*0.000000001)^5/(EXP(hP*cL/(H31*0.000000001*kB*$B$12))-1))*(1-EXP(-I31)))/1000000000000 -> 42.638311 | K31: =$B$15*(2*hP*cL^2/(H31*0.000000001)^5/(EXP(hP*cL/(H31*0.000000001*kB*$B$11))-1))/1000000000000 -> 43.438517 | L31: =(2*hP*cL^2/(H31*0.000000001)^5/(EXP(hP*cL/(H31*0.000000001*kB*$B$12))-1))/1000000000000 -> 3.0347681
E32: =6*6/30 -> 1.2 | F32: =$B$6*EXP(-E32)+(1-EXP(-E32)) -> 1.3614331 | G32: =1 -> 1 | H32: 372 | I32: =$B$14+$B$13*SUMPRODUCT($P$6:$P$27,EXP(0-((H32-$O$6:$O$27)/1.2)^2)) -> 0.024720175 | J32: =($B$15*(2*hP*cL^2/(H32*0.000000001)^5/(EXP(hP*cL/(H32*0.000000001*kB*$B$11))-1))*EXP(-I32)+(2*hP*cL^2/(H32*0.000000001)^5/(EXP(hP*cL/(H32*0.000000001*kB*$B$12))-1))*(1-EXP(-I32)))/1000000000000 -> 42.678295 | K32: =$B$15*(2*hP*cL^2/(H32*0.000000001)^5/(EXP(hP*cL/(H32*0.000000001*kB*$B$11))-1))/1000000000000 -> 43.669007 | L32: =(2*hP*cL^2/(H32*0.000000001)^5/(EXP(hP*cL/(H32*0.000000001*kB*$B$12))-1))/1000000000000 -> 3.0945664
E33: =6*7/30 -> 1.4 | F33: =$B$6*EXP(-E33)+(1-EXP(-E33)) -> 1.2959164 | G33: =1 -> 1 | H33: 374 | I33: =$B$14+$B$13*SUMPRODUCT($P$6:$P$27,EXP(0-((H33-$O$6:$O$27)/1.2)^2)) -> 0.054318227 | J33: =($B$15*(2*hP*cL^2/(H33*0.000000001)^5/(EXP(hP*cL/(H33*0.000000001*kB*$B$11))-1))*EXP(-I33)+(2*hP*cL^2/(H33*0.000000001)^5/(EXP(hP*cL/(H33*0.000000001*kB*$B$12))-1))*(1-EXP(-I33)))/1000000000000 -> 41.738271 | K33: =$B$15*(2*hP*cL^2/(H33*0.000000001)^5/(EXP(hP*cL/(H33*0.000000001*kB*$B$11))-1))/1000000000000 -> 43.892041 | L33: =(2*hP*cL^2/(H33*0.000000001)^5/(EXP(hP*cL/(H33*0.000000001*kB*$B$12))-1))/1000000000000 -> 3.1544322
E34: =6*8/30 -> 1.6 | F34: =$B$6*EXP(-E34)+(1-EXP(-E34)) -> 1.2422758 | G34: =1 -> 1 | H34: 376 | I34: =$B$14+$B$13*SUMPRODUCT($P$6:$P$27,EXP(0-((H34-$O$6:$O$27)/1.2)^2)) -> 0.054343379 | J34: =($B$15*(2*hP*cL^2/(H34*0.000000001)^5/(EXP(hP*cL/(H34*0.000000001*kB*$B$11))-1))*EXP(-I34)+(2*hP*cL^2/(H34*0.000000001)^5/(EXP(hP*cL/(H34*0.000000001*kB*$B$12))-1))*(1-EXP(-I34)))/1000000000000 -> 41.944692 | K34: =$B$15*(2*hP*cL^2/(H34*0.000000001)^5/(EXP(hP*cL/(H34*0.000000001*kB*$B$11))-1))/1000000000000 -> 44.10767 | L34: =(2*hP*cL^2/(H34*0.000000001)^5/(EXP(hP*cL/(H34*0.000000001*kB*$B$12))-1))/1000000000000 -> 3.214345
E35: =6*9/30 -> 1.8 | F35: =$B$6*EXP(-E35)+(1-EXP(-E35)) -> 1.1983587 | G35: =1 -> 1 | H35: 378 | I35: =$B$14+$B$13*SUMPRODUCT($P$6:$P$27,EXP(0-((H35-$O$6:$O$27)/1.2)^2)) -> 0.049710319 | J35: =($B$15*(2*hP*cL^2/(H35*0.000000001)^5/(EXP(hP*cL/(H35*0.000000001*kB*$B$11))-1))*EXP(-I35)+(2*hP*cL^2/(H35*0.000000001)^5/(EXP(hP*cL/(H35*0.000000001*kB*$B$12))-1))*(1-EXP(-I35)))/1000000000000 -> 42.325628 | K35: =$B$15*(2*hP*cL^2/(H35*0.000000001)^5/(EXP(hP*cL/(H35*0.000000001*kB*$B$11))-1))/1000000000000 -> 44.315943 | L35: =(2*hP*cL^2/(H35*0.000000001)^5/(EXP(hP*cL/(H35*0.000000001*kB*$B$12))-1))/1000000000000 -> 3.2742841
E36: =6*10/30 -> 2 | F36: =$B$6*EXP(-E36)+(1-EXP(-E36)) -> 1.1624023 | G36: =1 -> 1 | H36: 380 | I36: =$B$14+$B$13*SUMPRODUCT($P$6:$P$27,EXP(0-((H36-$O$6:$O$27)/1.2)^2)) -> 0.073790551 | J36: =($B$15*(2*hP*cL^2/(H36*0.000000001)^5/(EXP(hP*cL/(H36*0.000000001*kB*$B$11))-1))*EXP(-I36)+(2*hP*cL^2/(H36*0.000000001)^5/(EXP(hP*cL/(H36*0.000000001*kB*$B$12))-1))*(1-EXP(-I36)))/1000000000000 -> 41.587435 | K36: =$B$15*(2*hP*cL^2/(H36*0.000000001)^5/(EXP(hP*cL/(H36*0.000000001*kB*$B$11))-1))/1000000000000 -> 44.516915 | L36: =(2*hP*cL^2/(H36*0.000000001)^5/(EXP(hP*cL/(H36*0.000000001*kB*$B$12))-1))/1000000000000 -> 3.3342295
E37: =6*11/30 -> 2.2 | F37: =$B$6*EXP(-E37)+(1-EXP(-E37)) -> 1.1329638 | G37: =1 -> 1 | H37: 382 | I37: =$B$14+$B$13*SUMPRODUCT($P$6:$P$27,EXP(0-((H37-$O$6:$O$27)/1.2)^2)) -> 0.033710025 | J37: =($B$15*(2*hP*cL^2/(H37*0.000000001)^5/(EXP(hP*cL/(H37*0.000000001*kB*$B$11))-1))*EXP(-I37)+(2*hP*cL^2/(H37*0.000000001)^5/(EXP(hP*cL/(H37*0.000000001*kB*$B$12))-1))*(1-EXP(-I37)))/1000000000000 -> 43.341078 | K37: =$B$15*(2*hP*cL^2/(H37*0.000000001)^5/(EXP(hP*cL/(H37*0.000000001*kB*$B$11))-1))/1000000000000 -> 44.710644 | L37: =(2*hP*cL^2/(H37*0.000000001)^5/(EXP(hP*cL/(H37*0.000000001*kB*$B$12))-1))/1000000000000 -> 3.3941612
E38: =6*12/30 -> 2.4 | F38: =$B$6*EXP(-E38)+(1-EXP(-E38)) -> 1.1088615 | G38: =1 -> 1 | H38: 384 | I38: =$B$14+$B$13*SUMPRODUCT($P$6:$P$27,EXP(0-((H38-$O$6:$O$27)/1.2)^2)) -> 0.088039127 | J38: =($B$15*(2*hP*cL^2/(H38*0.000000001)^5/(EXP(hP*cL/(H38*0.000000001*kB*$B$11))-1))*EXP(-I38)+(2*hP*cL^2/(H38*0.000000001)^5/(EXP(hP*cL/(H38*0.000000001*kB*$B$12))-1))*(1-EXP(-I38)))/1000000000000 -> 41.404571 | K38: =$B$15*(2*hP*cL^2/(H38*0.000000001)^5/(EXP(hP*cL/(H38*0.000000001*kB*$B$11))-1))/1000000000000 -> 44.897189 | L38: =(2*hP*cL^2/(H38*0.000000001)^5/(EXP(hP*cL/(H38*0.000000001*kB*$B$12))-1))/1000000000000 -> 3.4540595
E39: =6*13/30 -> 2.6 | F39: =$B$6*EXP(-E39)+(1-EXP(-E39)) -> 1.0891283 | G39: =1 -> 1 | H39: 386 | I39: =$B$14+$B$13*SUMPRODUCT($P$6:$P$27,EXP(0-((H39-$O$6:$O$27)/1.2)^2)) -> 0.021788949 | J39: =($B$15*(2*hP*cL^2/(H39*0.000000001)^5/(EXP(hP*cL/(H39*0.000000001*kB*$B$11))-1))*EXP(-I39)+(2*hP*cL^2/(H39*0.000000001)^5/(EXP(hP*cL/(H39*0.000000001*kB*$B$12))-1))*(1-EXP(-I39)))/1000000000000 -> 44.180798 | K39: =$B$15*(2*hP*cL^2/(H39*0.000000001)^5/(EXP(hP*cL/(H39*0.000000001*kB*$B$11))-1))/1000000000000 -> 45.076611 | L39: =(2*hP*cL^2/(H39*0.000000001)^5/(EXP(hP*cL/(H39*0.000000001*kB*$B$12))-1))/1000000000000 -> 3.5139052
E40: =6*14/30 -> 2.8 | F40: =$B$6*EXP(-E40)+(1-EXP(-E40)) -> 1.0729721 | G40: =1 -> 1 | H40: 388 | I40: =$B$14+$B$13*SUMPRODUCT($P$6:$P$27,EXP(0-((H40-$O$6:$O$27)/1.2)^2)) -> 0.07135001 | J40: =($B$15*(2*hP*cL^2/(H40*0.000000001)^5/(EXP(hP*cL/(H40*0.000000001*kB*$B$11))-1))*EXP(-I40)+(2*hP*cL^2/(H40*0.000000001)^5/(EXP(hP*cL/(H40*0.000000001*kB*$B$12))-1))*(1-EXP(-I40)))/1000000000000 -> 42.379046 | K40: =$B$15*(2*hP*cL^2/(H40*0.000000001)^5/(EXP(hP*cL/(H40*0.000000001*kB*$B$11))-1))/1000000000000 -> 45.248977 | L40: =(2*hP*cL^2/(H40*0.000000001)^5/(EXP(hP*cL/(H40*0.000000001*kB*$B$12))-1))/1000000000000 -> 3.5736792
E41: =6*15/30 -> 3 | F41: =$B$6*EXP(-E41)+(1-EXP(-E41)) -> 1.0597445 | G41: =1 -> 1 | H41: 390 | I41: =$B$14+$B$13*SUMPRODUCT($P$6:$P$27,EXP(0-((H41-$O$6:$O$27)/1.2)^2)) -> 0.073982628 | J41: =($B$15*(2*hP*cL^2/(H41*0.000000001)^5/(EXP(hP*cL/(H41*0.000000001*kB*$B$11))-1))*EXP(-I41)+(2*hP*cL^2/(H41*0.000000001)^5/(EXP(hP*cL/(H41*0.000000001*kB*$B$12))-1))*(1-EXP(-I41)))/1000000000000 -> 42.434858 | K41: =$B$15*(2*hP*cL^2/(H41*0.000000001)^5/(EXP(hP*cL/(H41*0.000000001*kB*$B$11))-1))/1000000000000 -> 45.414351 | L41: =(2*hP*cL^2/(H41*0.000000001)^5/(EXP(hP*cL/(H41*0.000000001*kB*$B$12))-1))/1000000000000 -> 3.6333628
...

Sheet SA1 Saha-Boltzmann
A1: Lecture SA1 - Why are Balmer lines strongest in A stars?
A2: In LTE, excitation follows Boltzmann and ionisation follows Saha. The n=2 population (Balmer absorbers) peaks near 10 000 K.
A3: Equation: N_II n_e / N_I = (2 U_II/U_I)(2 pi m_e k T/h^2)^1.5 exp(-13.6 eV/kT); N2/N1 = 4 exp(-10.2 eV/kT)
A5: Inputs
A6: Temperature T | B6: 9900 | C6: K
A7: Electron pressure P_e | B7: 20 | C7: Pa
A9: Results
A10: Electron density n_e = P_e/kT | B10: =$B$7/(kB*$B$6) -> 1.4632264e+20 | C10: m^-3
A11: kT | B11: =kB*$B$6/eV -> 0.85311599 | C11: eV
A12: N2/N1 (Boltzmann) | B12: =4*EXP(-10.199*eV/(kB*$B$6)) -> 2.570812e-05
A13: N_II/N_I (Saha) | B13: =(2*PI()*mE*kB*$B$6/hP^2)^1.5*EXP(-13.598*eV/(kB*$B$6))/$B$10 -> 1.9439625
A14: Ionised fraction | B14: =$B$13/(1+$B$13) -> 0.66032177
A15: N2 / N_total (Balmer absorbers) | B15: =$B$12/(1+$B$12)/(1+$B$13) -> 8.7322644e-06
A16: Temperature of the Balmer peak | B16: =INDEX(E18:E288,MATCH(MAX(G18:G288),G18:G288,0)) -> 9900 | C16: K
E17: T [K] | F17: ionised fraction | G17: N2/N_total x 1e5
E18: 3000 | F18: =(2*PI()*mE*kB*E18/hP^2)^1.5*EXP(-13.598*eV/(kB*E18))/($B$7/(kB*E18))/(1+(2*PI()*mE*kB*E18/hP^2)^1.5*EXP(-13.598*eV/(kB*E18))/($B$7/(kB*E18))) -> 1.1778283e-17 | G18: =100000*(4*EXP(-10.199*eV/(kB*E18)))/(1+4*EXP(-10.199*eV/(kB*E18)))/(1+(2*PI()*mE*kB*E18/hP^2)^1.5*EXP(-13.598*eV/(kB*E18))/($B$7/(kB*E18))) -> 2.9409937e-12
E19: 3100 | F19: =(2*PI()*mE*kB*E19/hP^2)^1.5*EXP(-13.598*eV/(kB*E19))/($B$7/(kB*E19))/(1+(2*PI()*mE*kB*E19/hP^2)^1.5*EXP(-13.598*eV/(kB*E19))/($B$7/(kB*E19))) -> 6.9754865e-17 | G19: =100000*(4*EXP(-10.199*eV/(kB*E19)))/(1+4*EXP(-10.199*eV/(kB*E19)))/(1+(2*PI()*mE*kB*E19/hP^2)^1.5*EXP(-13.598*eV/(kB*E19))/($B$7/(kB*E19))) -> 1.0500011e-11
E20: 3200 | F20: =(2*PI()*mE*kB*E20/hP^2)^1.5*EXP(-13.598*eV/(kB*E20))/($B$7/(kB*E20))/(1+(2*PI()*mE*kB*E20/hP^2)^1.5*EXP(-13.598*eV/(kB*E20))/($B$7/(kB*E20))) -> 3.7057911e-16 | G20: =100000*(4*EXP(-10.199*eV/(kB*E20)))/(1+4*EXP(-10.199*eV/(kB*E20)))/(1+(2*PI()*mE*kB*E20/hP^2)^1.5*EXP(-13.598*eV/(kB*E20))/($B$7/(kB*E20))) -> 3.4621187e-11
E21: 3300 | F21: =(2*PI()*mE*kB*E21/hP^2)^1.5*EXP(-13.598*eV/(kB*E21))/($B$7/(kB*E21))/(1+(2*PI()*mE*kB*E21/hP^2)^1.5*EXP(-13.598*eV/(kB*E21))/($B$7/(kB*E21))) -> 1.7834368e-15 | G21: =100000*(4*EXP(-10.199*eV/(kB*E21)))/(1+4*EXP(-10.199*eV/(kB*E21)))/(1+(2*PI()*mE*kB*E21/hP^2)^1.5*EXP(-13.598*eV/(kB*E21))/($B$7/(kB*E21))) -> 1.061918e-10
E22: 3400 | F22: =(2*PI()*mE*kB*E22/hP^2)^1.5*EXP(-13.598*eV/(kB*E22))/($B$7/(kB*E22))/(1+(2*PI()*mE*kB*E22/hP^2)^1.5*EXP(-13.598*eV/(kB*E22))/($B$7/(kB*E22))) -> 7.8426448e-15 | G22: =100000*(4*EXP(-10.199*eV/(kB*E22)))/(1+4*EXP(-10.199*eV/(kB*E22)))/(1+(2*PI()*mE*kB*E22/hP^2)^1.5*EXP(-13.598*eV/(kB*E22))/($B$7/(kB*E22))) -> 3.0493531e-10
E23: 3500 | F23: =(2*PI()*mE*kB*E23/hP^2)^1.5*EXP(-13.598*eV/(kB*E23))/($B$7/(kB*E23))/(1+(2*PI()*mE*kB*E23/hP^2)^1.5*EXP(-13.598*eV/(kB*E23))/($B$7/(kB*E23))) -> 3.1755965e-14 | G23: =100000*(4*EXP(-10.199*eV/(kB*E23)))/(1+4*EXP(-10.199*eV/(kB*E23)))/(1+(2*PI()*mE*kB*E23/hP^2)^1.5*EXP(-13.598*eV/(kB*E23))/($B$7/(kB*E23))) -> 8.244159e-10
E24: 3600 | F24: =(2*PI()*mE*kB*E24/hP^2)^1.5*EXP(-13.598*eV/(kB*E24))/($B$7/(kB*E24))/(1+(2*PI()*mE*kB*E24/hP^2)^1.5*EXP(-13.598*eV/(kB*E24))/($B$7/(kB*E24))) -> 1.1920858e-13 | G24: =100000*(4*EXP(-10.199*eV/(kB*E24)))/(1+4*EXP(-10.199*eV/(kB*E24)))/(1+(2*PI()*mE*kB*E24/hP^2)^1.5*EXP(-13.598*eV/(kB*E24))/($B$7/(kB*E24))) -> 2.1090574e-09
E25: 3700 | F25: =(2*PI()*mE*kB*E25/hP^2)^1.5*EXP(-13.598*eV/(kB*E25))/($B$7/(kB*E25))/(1+(2*PI()*mE*kB*E25/hP^2)^1.5*EXP(-13.598*eV/(kB*E25))/($B$7/(kB*E25))) -> 4.1739943e-13 | G25: =100000*(4*EXP(-10.199*eV/(kB*E25)))/(1+4*EXP(-10.199*eV/(kB*E25)))/(1+(2*PI()*mE*kB*E25/hP^2)^1.5*EXP(-13.598*eV/(kB*E25))/($B$7/(kB*E25))) -> 5.1283721e-09
E26: 3800 | F26: =(2*PI()*mE*kB*E26/hP^2)^1.5*EXP(-13.598*eV/(kB*E26))/($B$7/(kB*E26))/(1+(2*PI()*mE*kB*E26/hP^2)^1.5*EXP(-13.598*eV/(kB*E26))/($B$7/(kB*E26))) -> 1.370642e-12 | G26: =100000*(4*EXP(-10.199*eV/(kB*E26)))/(1+4*EXP(-10.199*eV/(kB*E26)))/(1+(2*PI()*mE*kB*E26/hP^2)^1.5*EXP(-13.598*eV/(kB*E26))/($B$7/(kB*E26))) -> 1.1900374e-08
E27: 3900 | F27: =(2*PI()*mE*kB*E27/hP^2)^1.5*EXP(-13.598*eV/(kB*E27))/($B$7/(kB*E27))/(1+(2*PI()*mE*kB*E27/hP^2)^1.5*EXP(-13.598*eV/(kB*E27))/($B$7/(kB*E27))) -> 4.2417819e-12 | G27: =100000*(4*EXP(-10.199*eV/(kB*E27)))/(1+4*EXP(-10.199*eV/(kB*E27)))/(1+(2*PI()*mE*kB*E27/hP^2)^1.5*EXP(-13.598*eV/(kB*E27))/($B$7/(kB*E27))) -> 2.6448065e-08
E28: 4000 | F28: =(2*PI()*mE*kB*E28/hP^2)^1.5*EXP(-13.598*eV/(kB*E28))/($B$7/(kB*E28))/(1+(2*PI()*mE*kB*E28/hP^2)^1.5*EXP(-13.598*eV/(kB*E28))/($B$7/(kB*E28))) -> 1.2426175e-11 | G28: =100000*(4*EXP(-10.199*eV/(kB*E28)))/(1+4*EXP(-10.199*eV/(kB*E28)))/(1+(2*PI()*mE*kB*E28/hP^2)^1.5*EXP(-13.598*eV/(kB*E28))/($B$7/(kB*E28))) -> 5.6478813e-08
E29: 4100 | F29: =(2*PI()*mE*kB*E29/hP^2)^1.5*EXP(-13.598*eV/(kB*E29))/($B$7/(kB*E29))/(1+(2*PI()*mE*kB*E29/hP^2)^1.5*EXP(-13.598*eV/(kB*E29))/($B$7/(kB*E29))) -> 3.459541e-11 | G29: =100000*(4*EXP(-10.199*eV/(kB*E29)))/(1+4*EXP(-10.199*eV/(kB*E29)))/(1+(2*PI()*mE*kB*E29/hP^2)^1.5*EXP(-13.598*eV/(kB*E29))/($B$7/(kB*E29))) -> 1.1622631e-07
... E288: 30000 | F288: =(2*PI()*mE*kB*E288/hP^2)^1.5*EXP(-13.598*eV/(kB*E288))/($B$7/(kB*E288))/(1+(2*PI()*mE*kB*E288/hP^2)^1.5*EXP(-13.598*eV/(kB*E288))/($B$7/(kB*E288))) -> 0.99999926 | G288: =100000*(4*EXP(-10.199*eV/(kB*E288)))/(1+4*EXP(-10.199*eV/(kB*E288)))/(1+(2*PI()*mE*kB*E288/hP^2)^1.5*EXP(-13.598*eV/(kB*E288))/($B$7/(kB*E288))) -> 0.005320785

Sheet RT4 Eddington-Barbier
A1: Lecture RT4 - What depth do we see at each point of the stellar disk?
A2: The emergent intensity is S averaged with weight exp(-tau/mu)/mu. Eddington-Barbier: I(0,mu) ~ S(tau = mu), exact for linear S.
A3: Equation: S(tau) = a + b tau + c tau^2 -> I(0,mu) = a + b mu + 2 c mu^2; F = pi (a + 2b/3 + c) ~ pi S(2/3)
A5: Inputs
A6: a (surface value of S) | B6: 0.4
A7: b (gradient) | B7: 0.6
A8: c (curvature) | B8: 0
A9: mu = cos(theta) (1 = centre, 0 = limb) | B9: 0.5
A11: Results
A12: Exact I(0,mu) = a + b mu + 2 c mu^2 | B12: =$B$6+$B$7*$B$9+2*$B$8*$B$9^2 -> 0.7
A13: Eddington-Barbier S(tau = mu) | B13: =$B$6+$B$7*$B$9+$B$8*$B$9^2 -> 0.7
A14: Error of Eddington-Barbier | B14: =IF($B$12=0,0,($B$13-$B$12)/$B$12) -> 0
A15: Flux pi (a + 2b/3 + c) | B15: =PI()*($B$6+2*$B$7/3+$B$8) -> 2.5132741
A16: pi S(2/3) | B16: =PI()*($B$6+2*$B$7/3+$B$8*4/9) -> 2.5132741
A17: Limb/centre ratio I(0)/I(1) | B17: =$B$6/($B$6+$B$7+2*$B$8) -> 0.4
E19: mu | F19: I(mu)/I(1) | H19: tau | I19: S(tau) | J19: weight exp(-tau/mu)/mu
E20: =0/20 -> 0 | F20: =($B$6+$B$7*E20+2*$B$8*E20^2)/($B$6+$B$7+2*$B$8) -> 0.4 | H20: =3*0/40 -> 0 | I20: =$B$6+$B$7*H20+$B$8*H20^2 -> 0.4 | J20: =EXP(-H20/$B$9)/$B$9 -> 2
E21: =1/20 -> 0.05 | F21: =($B$6+$B$7*E21+2*$B$8*E21^2)/($B$6+$B$7+2*$B$8) -> 0.43 | H21: =3*1/40 -> 0.075 | I21: =$B$6+$B$7*H21+$B$8*H21^2 -> 0.445 | J21: =EXP(-H21/$B$9)/$B$9 -> 1.721416
E22: =2/20 -> 0.1 | F22: =($B$6+$B$7*E22+2*$B$8*E22^2)/($B$6+$B$7+2*$B$8) -> 0.46 | H22: =3*2/40 -> 0.15 | I22: =$B$6+$B$7*H22+$B$8*H22^2 -> 0.49 | J22: =EXP(-H22/$B$9)/$B$9 -> 1.4816364
E23: =3/20 -> 0.15 | F23: =($B$6+$B$7*E23+2*$B$8*E23^2)/($B$6+$B$7+2*$B$8) -> 0.49 | H23: =3*3/40 -> 0.225 | I23: =$B$6+$B$7*H23+$B$8*H23^2 -> 0.535 | J23: =EXP(-H23/$B$9)/$B$9 -> 1.2752563
E24: =4/20 -> 0.2 | F24: =($B$6+$B$7*E24+2*$B$8*E24^2)/($B$6+$B$7+2*$B$8) -> 0.52 | H24: =3*4/40 -> 0.3 | I24: =$B$6+$B$7*H24+$B$8*H24^2 -> 0.58 | J24: =EXP(-H24/$B$9)/$B$9 -> 1.0976233
E25: =5/20 -> 0.25 | F25: =($B$6+$B$7*E25+2*$B$8*E25^2)/($B$6+$B$7+2*$B$8) -> 0.55 | H25: =3*5/40 -> 0.375 | I25: =$B$6+$B$7*H25+$B$8*H25^2 -> 0.625 | J25: =EXP(-H25/$B$9)/$B$9 -> 0.94473311
E26: =6/20 -> 0.3 | F26: =($B$6+$B$7*E26+2*$B$8*E26^2)/($B$6+$B$7+2*$B$8) -> 0.58 | H26: =3*6/40 -> 0.45 | I26: =$B$6+$B$7*H26+$B$8*H26^2 -> 0.67 | J26: =EXP(-H26/$B$9)/$B$9 -> 0.81313932
E27: =7/20 -> 0.35 | F27: =($B$6+$B$7*E27+2*$B$8*E27^2)/($B$6+$B$7+2*$B$8) -> 0.61 | H27: =3*7/40 -> 0.525 | I27: =$B$6+$B$7*H27+$B$8*H27^2 -> 0.715 | J27: =EXP(-H27/$B$9)/$B$9 -> 0.6998755
E28: =8/20 -> 0.4 | F28: =($B$6+$B$7*E28+2*$B$8*E28^2)/($B$6+$B$7+2*$B$8) -> 0.64 | H28: =3*8/40 -> 0.6 | I28: =$B$6+$B$7*H28+$B$8*H28^2 -> 0.76 | J28: =EXP(-H28/$B$9)/$B$9 -> 0.60238842
E29: =9/20 -> 0.45 | F29: =($B$6+$B$7*E29+2*$B$8*E29^2)/($B$6+$B$7+2*$B$8) -> 0.67 | H29: =3*9/40 -> 0.675 | I29: =$B$6+$B$7*H29+$B$8*H29^2 -> 0.805 | J29: =EXP(-H29/$B$9)/$B$9 -> 0.51848052
E30: =10/20 -> 0.5 | F30: =($B$6+$B$7*E30+2*$B$8*E30^2)/($B$6+$B$7+2*$B$8) -> 0.7 | H30: =3*10/40 -> 0.75 | I30: =$B$6+$B$7*H30+$B$8*H30^2 -> 0.85 | J30: =EXP(-H30/$B$9)/$B$9 -> 0.44626032
E31: =11/20 -> 0.55 | F31: =($B$6+$B$7*E31+2*$B$8*E31^2)/($B$6+$B$7+2*$B$8) -> 0.73 | H31: =3*11/40 -> 0.825 | I31: =$B$6+$B$7*H31+$B$8*H31^2 -> 0.895 | J31: =EXP(-H31/$B$9)/$B$9 -> 0.38409982
E32: =12/20 -> 0.6 | F32: =($B$6+$B$7*E32+2*$B$8*E32^2)/($B$6+$B$7+2*$B$8) -> 0.76 | H32: =3*12/40 -> 0.9 | I32: =$B$6+$B$7*H32+$B$8*H32^2 -> 0.94 | J32: =EXP(-H32/$B$9)/$B$9 -> 0.33059778
E33: =13/20 -> 0.65 | F33: =($B$6+$B$7*E33+2*$B$8*E33^2)/($B$6+$B$7+2*$B$8) -> 0.79 | H33: =3*13/40 -> 0.975 | I33: =$B$6+$B$7*H33+$B$8*H33^2 -> 0.985 | J33: =EXP(-H33/$B$9)/$B$9 -> 0.28454814
E34: =14/20 -> 0.7 | F34: =($B$6+$B$7*E34+2*$B$8*E34^2)/($B$6+$B$7+2*$B$8) -> 0.82 | H34: =3*14/40 -> 1.05 | I34: =$B$6+$B$7*H34+$B$8*H34^2 -> 1.03 | J34: =EXP(-H34/$B$9)/$B$9 -> 0.24491286
E35: =15/20 -> 0.75 | F35: =($B$6+$B$7*E35+2*$B$8*E35^2)/($B$6+$B$7+2*$B$8) -> 0.85 | H35: =3*15/40 -> 1.125 | I35: =$B$6+$B$7*H35+$B$8*H35^2 -> 1.075 | J35: =EXP(-H35/$B$9)/$B$9 -> 0.21079845
E36: =16/20 -> 0.8 | F36: =($B$6+$B$7*E36+2*$B$8*E36^2)/($B$6+$B$7+2*$B$8) -> 0.88 | H36: =3*16/40 -> 1.2 | I36: =$B$6+$B$7*H36+$B$8*H36^2 -> 1.12 | J36: =EXP(-H36/$B$9)/$B$9 -> 0.18143591
E37: =17/20 -> 0.85 | F37: =($B$6+$B$7*E37+2*$B$8*E37^2)/($B$6+$B$7+2*$B$8) -> 0.91 | H37: =3*17/40 -> 1.275 | I37: =$B$6+$B$7*H37+$B$8*H37^2 -> 1.165 | J37: =EXP(-H37/$B$9)/$B$9 -> 0.15616333
E38: =18/20 -> 0.9 | F38: =($B$6+$B$7*E38+2*$B$8*E38^2)/($B$6+$B$7+2*$B$8) -> 0.94 | H38: =3*18/40 -> 1.35 | I38: =$B$6+$B$7*H38+$B$8*H38^2 -> 1.21 | J38: =EXP(-H38/$B$9)/$B$9 -> 0.13441103
E39: =19/20 -> 0.95 | F39: =($B$6+$B$7*E39+2*$B$8*E39^2)/($B$6+$B$7+2*$B$8) -> 0.97 | H39: =3*19/40 -> 1.425 | I39: =$B$6+$B$7*H39+$B$8*H39^2 -> 1.255 | J39: =EXP(-H39/$B$9)/$B$9 -> 0.11568864
E40: =20/20 -> 1 | F40: =($B$6+$B$7*E40+2*$B$8*E40^2)/($B$6+$B$7+2*$B$8) -> 1 | H40: =3*20/40 -> 1.5 | I40: =$B$6+$B$7*H40+$B$8*H40^2 -> 1.3 | J40: =EXP(-H40/$B$9)/$B$9 -> 0.099574137
H41: =3*21/40 -> 1.575 | I41: =$B$6+$B$7*H41+$B$8*H41^2 -> 1.345 | J41: =EXP(-H41/$B$9)/$B$9 -> 0.085704254
H42: =3*22/40 -> 1.65 | I42: =$B$6+$B$7*H42+$B$8*H42^2 -> 1.39 | J42: =EXP(-H42/$B$9)/$B$9 -> 0.073766335
H43: =3*23/40 -> 1.725 | I43: =$B$6+$B$7*H43+$B$8*H43^2 -> 1.435 | J43: =EXP(-H43/$B$9)/$B$9 -> 0.063491273
...

Sheet RT4 Scattering
A1: Lecture RT4 - Why is S below B at the surface of an isothermal scattering atmosphere?
A2: Photons scatter ~1/eps times before destruction and leak out within tau ~ 1/sqrt(eps) of the surface, so J and S fall below B there.
A3: Equation: S = eps B + (1-eps) J; Eddington: J = B [1 - exp(-sqrt(3 eps) tau)/(1 + 2 sqrt(eps/3))]; exact: S(0) = sqrt(eps) B
A5: Inputs
A6: Destruction probability eps | B6: 0.01
A8: Results
A9: Exact S(0)/B = sqrt(eps) | B9: =SQRT($B$6) -> 0.1
A10: Eddington S(0)/B | B10: =$B$6+(1-$B$6)*(1-1/(1+2*SQRT($B$6/3))) -> 0.11248178
A11: Eddington error at the surface | B11: =B10/B9-1 -> 0.12481777
A12: Thermalisation depth 1/sqrt(eps) | B12: =1/SQRT($B$6) -> 10
A13: Eddington thermalisation length 1/sqrt(3 eps) | B13: =1/SQRT(3*$B$6) -> 5.7735027
A16: Exact numerical S(0)/B (Lambda matrix) for comparison: see sheet Data, columns I-K. | E16: tau | F16: S/B (Eddington) | G16: J/B (Eddington)
E17: 0.001 | F17: =$B$6+(1-$B$6)*(1-EXP(-SQRT(3*$B$6)*E17)/(1+2*SQRT($B$6/3))) -> 0.11263549 | G17: =1-EXP(-SQRT(3*$B$6)*E17)/(1+2*SQRT($B$6/3)) -> 0.10367221
E18: 0.0013335214 | F18: =$B$6+(1-$B$6)*(1-EXP(-SQRT(3*$B$6)*E18)/(1+2*SQRT($B$6/3))) -> 0.11268675 | G18: =1-EXP(-SQRT(3*$B$6)*E18)/(1+2*SQRT($B$6/3)) -> 0.10372399
A19: Rosseland mean calculator (3 frequency bands) | E19: 0.0017782794 | F19: =$B$6+(1-$B$6)*(1-EXP(-SQRT(3*$B$6)*E19)/(1+2*SQRT($B$6/3))) -> 0.1127551 | G19: =1-EXP(-SQRT(3*$B$6)*E19)/(1+2*SQRT($B$6/3)) -> 0.10379303
A20: Band weights must add to 1 (fraction of dB/dT in each band). | E20: 0.0023713737 | F20: =$B$6+(1-$B$6)*(1-EXP(-SQRT(3*$B$6)*E20)/(1+2*SQRT($B$6/3))) -> 0.11284624 | G20: =1-EXP(-SQRT(3*$B$6)*E20)/(1+2*SQRT($B$6/3)) -> 0.10388509
A21: Weight band 1 | B21: 0.5 | E21: 0.0031622777 | F21: =$B$6+(1-$B$6)*(1-EXP(-SQRT(3*$B$6)*E21)/(1+2*SQRT($B$6/3))) -> 0.11296776 | G21: =1-EXP(-SQRT(3*$B$6)*E21)/(1+2*SQRT($B$6/3)) -> 0.10400784
A22: Weight band 2 | B22: 0.3 | E22: 0.004216965 | F22: =$B$6+(1-$B$6)*(1-EXP(-SQRT(3*$B$6)*E22)/(1+2*SQRT($B$6/3))) -> 0.11312978 | G22: =1-EXP(-SQRT(3*$B$6)*E22)/(1+2*SQRT($B$6/3)) -> 0.1041715
A23: Weight band 3 | B23: 0.2 | E23: 0.0056234133 | F23: =$B$6+(1-$B$6)*(1-EXP(-SQRT(3*$B$6)*E23)/(1+2*SQRT($B$6/3))) -> 0.1133458 | G23: =1-EXP(-SQRT(3*$B$6)*E23)/(1+2*SQRT($B$6/3)) -> 0.1043897
A24: Opacity band 1 | B24: 1 | C24: m^2/kg | E24: 0.0074989421 | F24: =$B$6+(1-$B$6)*(1-EXP(-SQRT(3*$B$6)*E24)/(1+2*SQRT($B$6/3))) -> 0.11363379 | G24: =1-EXP(-SQRT(3*$B$6)*E24)/(1+2*SQRT($B$6/3)) -> 0.10468059
A25: Opacity band 2 | B25: 10 | C25: m^2/kg | E25: 0.01 | F25: =$B$6+(1-$B$6)*(1-EXP(-SQRT(3*$B$6)*E25)/(1+2*SQRT($B$6/3))) -> 0.11401767 | G25: =1-EXP(-SQRT(3*$B$6)*E25)/(1+2*SQRT($B$6/3)) -> 0.10506836
A26: Opacity band 3 | B26: 1000 | C26: m^2/kg | E26: 0.013335214 | F26: =$B$6+(1-$B$6)*(1-EXP(-SQRT(3*$B$6)*E26)/(1+2*SQRT($B$6/3))) -> 0.11452934 | G26: =1-EXP(-SQRT(3*$B$6)*E26)/(1+2*SQRT($B$6/3)) -> 0.10558519
A27: Rosseland mean (harmonic) | B27: =($B$21+$B$22+$B$23)/($B$21/$B$24+$B$22/$B$25+$B$23/$B$26) -> 1.8860807 | C27: m^2/kg | E27: 0.017782794 | F27: =$B$6+(1-$B$6)*(1-EXP(-SQRT(3*$B$6)*E27)/(1+2*SQRT($B$6/3))) -> 0.11521119 | G27: =1-EXP(-SQRT(3*$B$6)*E27)/(1+2*SQRT($B$6/3)) -> 0.10627393
A28: Planck-type mean (arithmetic) | B28: =($B$21*$B$24+$B$22*$B$25+$B$23*$B$26)/($B$21+$B$22+$B$23) -> 203.5 | C28: m^2/kg | E28: 0.023713737 | F28: =$B$6+(1-$B$6)*(1-EXP(-SQRT(3*$B$6)*E28)/(1+2*SQRT($B$6/3))) -> 0.11611964 | G28: =1-EXP(-SQRT(3*$B$6)*E28)/(1+2*SQRT($B$6/3)) -> 0.10719156
E29: 0.031622777 | F29: =$B$6+(1-$B$6)*(1-EXP(-SQRT(3*$B$6)*E29)/(1+2*SQRT($B$6/3))) -> 0.11732963 | G29: =1-EXP(-SQRT(3*$B$6)*E29)/(1+2*SQRT($B$6/3)) -> 0.10841376
E30: 0.04216965 | F30: =$B$6+(1-$B$6)*(1-EXP(-SQRT(3*$B$6)*E30)/(1+2*SQRT($B$6/3))) -> 0.11894059 | G30: =1-EXP(-SQRT(3*$B$6)*E30)/(1+2*SQRT($B$6/3)) -> 0.110041
E31: 0.056234133 | F31: =$B$6+(1-$B$6)*(1-EXP(-SQRT(3*$B$6)*E31)/(1+2*SQRT($B$6/3))) -> 0.12108428 | G31: =1-EXP(-SQRT(3*$B$6)*E31)/(1+2*SQRT($B$6/3)) -> 0.11220634
E32: 0.074989421 | F32: =$B$6+(1-$B$6)*(1-EXP(-SQRT(3*$B$6)*E32)/(1+2*SQRT($B$6/3))) -> 0.12393481 | G32: =1-EXP(-SQRT(3*$B$6)*E32)/(1+2*SQRT($B$6/3)) -> 0.11508567
E33: 0.1 | F33: =$B$6+(1-$B$6)*(1-EXP(-SQRT(3*$B$6)*E33)/(1+2*SQRT($B$6/3))) -> 0.12772168 | G33: =1-EXP(-SQRT(3*$B$6)*E33)/(1+2*SQRT($B$6/3)) -> 0.11891079
E34: 0.13335214 | F34: =$B$6+(1-$B$6)*(1-EXP(-SQRT(3*$B$6)*E34)/(1+2*SQRT($B$6/3))) -> 0.1327461 | G34: =1-EXP(-SQRT(3*$B$6)*E34)/(1+2*SQRT($B$6/3)) -> 0.12398596
E35: 0.17782794 | F35: =$B$6+(1-$B$6)*(1-EXP(-SQRT(3*$B$6)*E35)/(1+2*SQRT($B$6/3))) -> 0.13940126 | G35: =1-EXP(-SQRT(3*$B$6)*E35)/(1+2*SQRT($B$6/3)) -> 0.13070835
E36: 0.23713737 | F36: =$B$6+(1-$B$6)*(1-EXP(-SQRT(3*$B$6)*E36)/(1+2*SQRT($B$6/3))) -> 0.14819668 | G36: =1-EXP(-SQRT(3*$B$6)*E36)/(1+2*SQRT($B$6/3)) -> 0.1395926
E37: 0.31622777 | F37: =$B$6+(1-$B$6)*(1-EXP(-SQRT(3*$B$6)*E37)/(1+2*SQRT($B$6/3))) -> 0.15978585 | G37: =1-EXP(-SQRT(3*$B$6)*E37)/(1+2*SQRT($B$6/3)) -> 0.15129884
E38: 0.4216965 | F38: =$B$6+(1-$B$6)*(1-EXP(-SQRT(3*$B$6)*E38)/(1+2*SQRT($B$6/3))) -> 0.17499531 | G38: =1-EXP(-SQRT(3*$B$6)*E38)/(1+2*SQRT($B$6/3)) -> 0.16666192
E39: 0.56234133 | F39: =$B$6+(1-$B$6)*(1-EXP(-SQRT(3*$B$6)*E39)/(1+2*SQRT($B$6/3))) -> 0.19484993 | G39: =1-EXP(-SQRT(3*$B$6)*E39)/(1+2*SQRT($B$6/3)) -> 0.1867171
E40: 0.74989421 | F40: =$B$6+(1-$B$6)*(1-EXP(-SQRT(3*$B$6)*E40)/(1+2*SQRT($B$6/3))) -> 0.22058506 | G40: =1-EXP(-SQRT(3*$B$6)*E40)/(1+2*SQRT($B$6/3)) -> 0.21271218
... E69: 3162.2777 | F69: =$B$6+(1-$B$6)*(1-EXP(-SQRT(3*$B$6)*E69)/(1+2*SQRT($B$6/3))) -> 1 | G69: =1-EXP(-SQRT(3*$B$6)*E69)/(1+2*SQRT($B$6/3)) -> 1

Sheet SA4 Gray atmosphere
A1: Lecture SA4 - The complete gray LTE atmosphere
A2: Exact solution (Hopf q, Chandrasekhar H) vs Eddington. The model scales with T_eff; limb darkening and spectrum are integrated numerically.
A3: Equation: T^4 = 3/4 T_eff^4 [tau + q(tau)]; I_lambda(0,mu) = Int B_lambda(T(tau)) exp(-tau/mu) dtau/mu; F_lambda = 2 pi Int B_lambda E2 dtau; P = g tau / kappa
A5: Inputs
A6: Effective temperature T_eff | B6: 5772 | C6: K
A7: Wavelength for limb darkening | B7: 500 | C7: nm
A8: Surface gravity log g (cgs) | B8: 4.44
A9: Mean opacity kappa | B9: 0.03 | C9: m^2/kg
A11: Results
A12: Surface T(0), exact | B12: =$B$6*(0.75*INDEX(Data!$B$4:$B$74,1))^0.25 -> 4682.1541 | C12: K
A13: Surface T(0), Eddington | B13: =$B$6*0.5^0.25 -> 4853.6541 | C13: K
A14: T at tau = 1 (Eddington) | B14: =$B$6*(0.75*(1+2/3))^0.25 -> 6103.1469 | C14: K
A15: Pressure at tau = 2/3: P = g tau/kappa | B15: =10^$B$8/100*(2/3)/$B$9 -> 6120.5082 | C15: Pa
A16: Density at tau = 2/3 (mu_mol = 1.3) | B16: =$B$15*1.3*mH/(kB*$B$6) -> 0.00016708865 | C16: kg m^-3
A17: Energy check: Int F_lambda dlambda / sigma T_eff^4 | B17: =SUMPRODUCT(T31:T150,U31:U150)/(sigSB*B6^4) -> 1.0045294 | C17: (should be ~1)
M19: mu | N19: I_lambda(0,mu) | O19: I/I(1) at lambda | P19: Eddington (2+3mu)/5 | Q19: bolometric exact
M20: 0.02 | N20: =SUMPRODUCT($K$31:$K$101,EXP(-$E$31:$E$101/M20)/M20,$H$31:$H$101) -> 9.0128485e+12 | O20: =N20/N40 -> 0.26173274 | P20: =(2+3*M20)/5 -> 0.412 | Q20: =INDEX(Data!$G$4:$G$24,MATCH(ROUND(M20*20,0)/20,Data!$E$4:$E$24,1)) -> 0.34390136
M21: 0.05 | N21: =SUMPRODUCT($K$31:$K$101,EXP(-$E$31:$E$101/M21)/M21,$H$31:$H$101) -> 9.9901388e+12 | O21: =N21/N40 -> 0.29011321 | P21: =(2+3*M21)/5 -> 0.43 | Q21: =INDEX(Data!$G$4:$G$24,MATCH(ROUND(M21*20,0)/20,Data!$E$4:$E$24,1)) -> 0.39086964
M22: 0.1 | N22: =SUMPRODUCT($K$31:$K$101,EXP(-$E$31:$E$101/M22)/M22,$H$31:$H$101) -> 1.148252e+13 | O22: =N22/N40 -> 0.33345191 | P22: =(2+3*M22)/5 -> 0.46 | Q22: =INDEX(Data!$G$4:$G$24,MATCH(ROUND(M22*20,0)/20,Data!$E$4:$E$24,1)) -> 0.42896552
M23: 0.15 | N23: =SUMPRODUCT($K$31:$K$101,EXP(-$E$31:$E$101/M23)/M23,$H$31:$H$101) -> 1.2902465e+13 | O23: =N23/N40 -> 0.37468706 | P23: =(2+3*M23)/5 -> 0.49 | Q23: =INDEX(Data!$G$4:$G$24,MATCH(ROUND(M23*20,0)/20,Data!$E$4:$E$24,1)) -> 0.46455351
M24: 0.2 | N24: =SUMPRODUCT($K$31:$K$101,EXP(-$E$31:$E$101/M24)/M24,$H$31:$H$101) -> 1.4283126e+13 | O24: =N24/N40 -> 0.41478138 | P24: =(2+3*M24)/5 -> 0.52 | Q24: =INDEX(Data!$G$4:$G$24,MATCH(ROUND(M24*20,0)/20,Data!$E$4:$E$24,1)) -> 0.49877783
M25: 0.25 | N25: =SUMPRODUCT($K$31:$K$101,EXP(-$E$31:$E$101/M25)/M25,$H$31:$H$101) -> 1.5637404e+13 | O25: =N25/N40 -> 0.45410955 | P25: =(2+3*M25)/5 -> 0.55 | Q25: =INDEX(Data!$G$4:$G$24,MATCH(ROUND(M25*20,0)/20,Data!$E$4:$E$24,1)) -> 0.5321276
M26: 0.3 | N26: =SUMPRODUCT($K$31:$K$101,EXP(-$E$31:$E$101/M26)/M26,$H$31:$H$101) -> 1.6971691e+13 | O26: =N26/N40 -> 0.4928572 | P26: =(2+3*M26)/5 -> 0.58 | Q26: =INDEX(Data!$G$4:$G$24,MATCH(ROUND(M26*20,0)/20,Data!$E$4:$E$24,1)) -> 0.56486564
M27: 0.35 | N27: =SUMPRODUCT($K$31:$K$101,EXP(-$E$31:$E$101/M27)/M27,$H$31:$H$101) -> 1.8289608e+13 | O27: =N27/N40 -> 0.53112946 | P27: =(2+3*M27)/5 -> 0.61 | Q27: =INDEX(Data!$G$4:$G$24,MATCH(ROUND(M27*20,0)/20,Data!$E$4:$E$24,1)) -> 0.59715161
M28: 0.4 | N28: =SUMPRODUCT($K$31:$K$101,EXP(-$E$31:$E$101/M28)/M28,$H$31:$H$101) -> 1.9593401e+13 | O28: =N28/N40 -> 0.56899154 | P28: =(2+3*M28)/5 -> 0.64 | Q28: =INDEX(Data!$G$4:$G$24,MATCH(ROUND(M28*20,0)/20,Data!$E$4:$E$24,1)) -> 0.62909037
M29: 0.45 | N29: =SUMPRODUCT($K$31:$K$101,EXP(-$E$31:$E$101/M29)/M29,$H$31:$H$101) -> 2.0884561e+13 | O29: =N29/N40 -> 0.60648677 | P29: =(2+3*M29)/5 -> 0.67 | Q29: =INDEX(Data!$G$4:$G$24,MATCH(ROUND(M29*20,0)/20,Data!$E$4:$E$24,1)) -> 0.66075474 | S29: Emergent spectrum (20 nm - 100 um, used for the energy check)
E30: tau | F30: Hopf q | G30: E2(tau) | H30: trapezoid weight | I30: T exact [K] | J30: T Eddington [K] | K30: B_lambda(T) at chosen lambda | M30: 0.5 | N30: =SUMPRODUCT($K$31:$K$101,EXP(-$E$31:$E$101/M30)/M30,$H$31:$H$101) -> 22164135050376 | O30: =N30/N40 -> 0.64364556 | P30: =(2+3*M30)/5 -> 0.7 | Q30: =INDEX(Data!$G$4:$G$24,MATCH(ROUND(M30*20,0)/20,Data!$E$4:$E$24,1)) -> 0.69219736 | S30: lambda [nm] | T30: F_lambda gray LTE | U30: d lambda weight [m] | V30: pi B_lambda(T_eff)
E31: =INDEX(Data!$A$4:$A$74,1) -> 0 | F31: =INDEX(Data!$B$4:$B$74,1) -> 0.57731952 | G31: =INDEX(Data!$C$4:$C$74,1) -> 1 | H31: =(E32-E31)/2 -> 0.0005 | I31: =$B$6*(0.75*(E31+F31))^0.25 -> 4682.1541 | J31: =$B$6*(0.75*(E31+2/3))^0.25 -> 4853.6541 | K31: =2*hP*cL^2/($B$7*0.000000001)^5/(EXP(hP*cL/($B$7*0.000000001*kB*I31))-1) -> 8.1832536e+12 | M31: 0.55 | N31: =SUMPRODUCT($K$31:$K$101,EXP(-$E$31:$E$101/M31)/M31,$H$31:$H$101) -> 2.3432896e+13 | O31: =N31/N40 -> 0.68049031 | P31: =(2+3*M31)/5 -> 0.73 | Q31: =INDEX(Data!$G$4:$G$24,MATCH(ROUND(M31*20,0)/20,Data!$E$4:$E$24,1)) -> 0.72345753 | S31: 20 | T31: =2*PI()*SUMPRODUCT(2*hP*cL^2/(S31*0.000000001)^5/(EXP(hP*cL/(S31*0.000000001*kB*$I$31:$I$101))-1),$G$31:$G$101,$H$31:$H$101) -> 2.3091236e-13 | U31: =(S32-S31)/2*0.000000001 -> 7.42e-10 | V31: =PI()*2*hP*cL^2/(S31*0.000000001)^5/(EXP(hP*cL/(S31*0.000000001*kB*$B$6))-1) -> 8.709522e-32
E32: =INDEX(Data!$A$4:$A$74,2) -> 0.001 | F32: =INDEX(Data!$B$4:$B$74,2) -> 0.57905525 | G32: =INDEX(Data!$C$4:$C$74,2) -> 0.99266896 | H32: =(E33-E31)/2 -> 0.00058057164 | I32: =$B$6*(0.75*(E32+F32))^0.25 -> 4687.691 | J32: =$B$6*(0.75*(E32+2/3))^0.25 -> 4855.4732 | K32: =2*hP*cL^2/($B$7*0.000000001)^5/(EXP(hP*cL/($B$7*0.000000001*kB*I32))-1) -> 8.2430028e+12 | M32: 0.6 | N32: =SUMPRODUCT($K$31:$K$101,EXP(-$E$31:$E$101/M32)/M32,$H$31:$H$101) -> 2.4691434e+13 | O32: =N32/N40 -> 0.71703823 | P32: =(2+3*M32)/5 -> 0.76 | Q32: =INDEX(Data!$G$4:$G$24,MATCH(ROUND(M32*20,0)/20,Data!$E$4:$E$24,1)) -> 0.75456533 | S32: 21.484 | T32: =2*PI()*SUMPRODUCT(2*hP*cL^2/(S32*0.000000001)^5/(EXP(hP*cL/(S32*0.000000001*kB*$I$31:$I$101))-1),$G$31:$G$101,$H$31:$H$101) -> 1.6750552e-11 | U32: =(S33-S31)/2*0.000000001 -> 1.539e-09 | V32: =PI()*2*hP*cL^2/(S32*0.000000001)^5/(EXP(hP*cL/(S32*0.000000001*kB*$B$6))-1) -> 3.3376221e-28
E33: =INDEX(Data!$A$4:$A$74,3) -> 0.0011611433 | F33: =INDEX(Data!$B$4:$B$74,3) -> 0.57928538 | G33: =INDEX(Data!$C$4:$C$74,3) -> 0.991661 | H33: =(E34-E32)/2 -> 0.00017412687 | I33: =$B$6*(0.75*(E33+F33))^0.25 -> 4688.4813 | J33: =$B$6*(0.75*(E33+2/3))^0.25 -> 4855.7662 | K33: =2*hP*cL^2/($B$7*0.000000001)^5/(EXP(hP*cL/($B$7*0.000000001*kB*I33))-1) -> 8.2515552e+12 | M33: 0.65 | N33: =SUMPRODUCT($K$31:$K$101,EXP(-$E$31:$E$101/M33)/M33,$H$31:$H$101) -> 2.5940223e+13 | O33: =N33/N40 -> 0.75330298 | P33: =(2+3*M33)/5 -> 0.79 | Q33: =INDEX(Data!$G$4:$G$24,MATCH(ROUND(M33*20,0)/20,Data!$E$4:$E$24,1)) -> 0.78554432 | S33: 23.078 | T33: =2*PI()*SUMPRODUCT(2*hP*cL^2/(S33*0.000000001)^5/(EXP(hP*cL/(S33*0.000000001*kB*$I$31:$I$101))-1),$G$31:$G$101,$H$31:$H$101) -> 9.389856e-10 | U33: =(S34-S32)/2*0.000000001 -> 1.653e-09 | V33: =PI()*2*hP*cL^2/(S33*0.000000001)^5/(EXP(hP*cL/(S33*0.000000001*kB*$B$6))-1) -> 7.0534284e-25
E34: =INDEX(Data!$A$4:$A$74,4) -> 0.0013482537 | F34: =INDEX(Data!$B$4:$B$74,4) -> 0.57954469 | G34: =INDEX(Data!$C$4:$C$74,4) -> 0.99051854 | H34: =(E35-E33)/2 -> 0.00020218624 | I34: =$B$6*(0.75*(E34+F34))^0.25 -> 4689.3826 | J34: =$B$6*(0.75*(E34+2/3))^0.25 -> 4856.1062 | K34: =2*hP*cL^2/($B$7*0.000000001)^5/(EXP(hP*cL/($B$7*0.000000001*kB*I34))-1) -> 8.2613148e+12 | M34: 0.7 | N34: =SUMPRODUCT($K$31:$K$101,EXP(-$E$31:$E$101/M34)/M34,$H$31:$H$101) -> 2.7179647e+13 | O34: =N34/N40 -> 0.78929581 | P34: =(2+3*M34)/5 -> 0.82 | Q34: =INDEX(Data!$G$4:$G$24,MATCH(ROUND(M34*20,0)/20,Data!$E$4:$E$24,1)) -> 0.8164132 | S34: 24.79 | T34: =2*PI()*SUMPRODUCT(2*hP*cL^2/(S34*0.000000001)^5/(EXP(hP*cL/(S34*0.000000001*kB*$I$31:$I$101))-1),$G$31:$G$101,$H$31:$H$101) -> 4.1259537e-08 | U34: =(S35-S33)/2*0.000000001 -> 1.776e-09 | V34: =PI()*2*hP*cL^2/(S34*0.000000001)^5/(EXP(hP*cL/(S34*0.000000001*kB*$B$6))-1) -> 8.5610545e-22
E35: =INDEX(Data!$A$4:$A$74,5) -> 0.0015655158 | F35: =INDEX(Data!$B$4:$B$74,5) -> 0.57983662 | G35: =INDEX(Data!$C$4:$C$74,5) -> 0.98922439 | H35: =(E36-E34)/2 -> 0.0002347672 | I35: =$B$6*(0.75*(E35+F35))^0.25 -> 4690.4099 | J35: =$B$6*(0.75*(E35+2/3))^0.25 -> 4856.501 | K35: =2*hP*cL^2/($B$7*0.000000001)^5/(EXP(hP*cL/($B$7*0.000000001*kB*I35))-1) -> 8.2724495e+12 | M35: 0.75 | N35: =SUMPRODUCT($K$31:$K$101,EXP(-$E$31:$E$101/M35)/M35,$H$31:$H$101) -> 2.8410035e+13 | O35: =N35/N40 -> 0.82502622 | P35: =(2+3*M35)/5 -> 0.85 | Q35: =INDEX(Data!$G$4:$G$24,MATCH(ROUND(M35*20,0)/20,Data!$E$4:$E$24,1)) -> 0.84718713 | S35: 26.63 | T35: =2*PI()*SUMPRODUCT(2*hP*cL^2/(S35*0.000000001)^5/(EXP(hP*cL/(S35*0.000000001*kB*$I$31:$I$101))-1),$G$31:$G$101,$H$31:$H$101) -> 1.444051e-06 | U35: =(S36-S34)/2*0.000000001 -> 1.9075e-09 | V35: =PI()*2*hP*cL^2/(S35*0.000000001)^5/(EXP(hP*cL/(S35*0.000000001*kB*$B$6))-1) -> 6.2283847e-19
E36: =INDEX(Data!$A$4:$A$74,6) -> 0.0018177881 | F36: =INDEX(Data!$B$4:$B$74,6) -> 0.58016498 | G36: =INDEX(Data!$C$4:$C$74,6) -> 0.98775933 | H36: =(E37-E35)/2 -> 0.00027259835 | I36: =$B$6*(0.75*(E36+F36))^0.25 -> 4691.5805 | J36: =$B$6*(0.75*(E36+2/3))^0.25 -> 4856.9593 | K36: =2*hP*cL^2/($B$7*0.000000001)^5/(EXP(hP*cL/($B$7*0.000000001*kB*I36))-1) -> 8.2851499e+12 | M36: 0.8 | N36: =SUMPRODUCT($K$31:$K$101,EXP(-$E$31:$E$101/M36)/M36,$H$31:$H$101) -> 2.9631669e+13 | O36: =N36/N40 -> 0.86050242 | P36: =(2+3*M36)/5 -> 0.88 | Q36: =INDEX(Data!$G$4:$G$24,MATCH(ROUND(M36*20,0)/20,Data!$E$4:$E$24,1)) -> 0.87787849 | S36: 28.605 | T36: =2*PI()*SUMPRODUCT(2*hP*cL^2/(S36*0.000000001)^5/(EXP(hP*cL/(S36*0.000000001*kB*$I$31:$I$101))-1),$G$31:$G$101,$H$31:$H$101) -> 4.0591053e-05 | U36: =(S37-S35)/2*0.000000001 -> 2.049e-09 | V36: =PI()*2*hP*cL^2/(S36*0.000000001)^5/(EXP(hP*cL/(S36*0.000000001*kB*$B$6))-1) -> 2.7911451e-16
E37: =INDEX(Data!$A$4:$A$74,7) -> 0.0021107125 | F37: =INDEX(Data!$B$4:$B$74,7) -> 0.58053398 | G37: =INDEX(Data!$C$4:$C$74,7) -> 0.98610187 | H37: =(E38-E36)/2 -> 0.00031652575 | I37: =$B$6*(0.75*(E37+F37))^0.25 -> 4692.9139 | J37: =$B$6*(0.75*(E37+2/3))^0.25 -> 4857.4913 | K37: =2*hP*cL^2/($B$7*0.000000001)^5/(EXP(hP*cL/($B$7*0.000000001*kB*I37))-1) -> 8.2996327e+12 | M37: 0.85 | N37: =SUMPRODUCT($K$31:$K$101,EXP(-$E$31:$E$101/M37)/M37,$H$31:$H$101) -> 3.0844798e+13 | O37: =N37/N40 -> 0.89573166 | P37: =(2+3*M37)/5 -> 0.91 | Q37: =INDEX(Data!$G$4:$G$24,MATCH(ROUND(M37*20,0)/20,Data!$E$4:$E$24,1)) -> 0.90849753 | S37: 30.728 | T37: =2*PI()*SUMPRODUCT(2*hP*cL^2/(S37*0.000000001)^5/(EXP(hP*cL/(S37*0.000000001*kB*$I$31:$I$101))-1),$G$31:$G$101,$H$31:$H$101) -> 0.0009320383 | U37: =(S38-S36)/2*0.000000001 -> 2.2015e-09 | V37: =PI()*2*hP*cL^2/(S37*0.000000001)^5/(EXP(hP*cL/(S37*0.000000001*kB*$B$6))-1) -> 8.0360141e-14
E38: =INDEX(Data!$A$4:$A$74,8) -> 0.0024508396 | F38: =INDEX(Data!$B$4:$B$74,8) -> 0.58094821 | G38: =INDEX(Data!$C$4:$C$74,8) -> 0.98422803 | H38: =(E39-E37)/2 -> 0.00036753175 | I38: =$B$6*(0.75*(E38+F38))^0.25 -> 4694.4322 | J38: =$B$6*(0.75*(E38+2/3))^0.25 -> 4858.1088 | K38: =2*hP*cL^2/($B$7*0.000000001)^5/(EXP(hP*cL/($B$7*0.000000001*kB*I38))-1) -> 8.3161441e+12 | M38: 0.9 | N38: =SUMPRODUCT($K$31:$K$101,EXP(-$E$31:$E$101/M38)/M38,$H$31:$H$101) -> 32049648648016 | O38: =N38/N40 -> 0.93072046 | P38: =(2+3*M38)/5 -> 0.94 | Q38: =INDEX(Data!$G$4:$G$24,MATCH(ROUND(M38*20,0)/20,Data!$E$4:$E$24,1)) -> 0.93905282 | S38: 33.008 | T38: =2*PI()*SUMPRODUCT(2*hP*cL^2/(S38*0.000000001)^5/(EXP(hP*cL/(S38*0.000000001*kB*$I$31:$I$101))-1),$G$31:$G$101,$H$31:$H$101) -> 0.017628052 | U38: =(S39-S37)/2*0.000000001 -> 2.3645e-09 | V38: =PI()*2*hP*cL^2/(S38*0.000000001)^5/(EXP(hP*cL/(S38*0.000000001*kB*$B$6))-1) -> 1.5244884e-11
E39: =INDEX(Data!$A$4:$A$74,9) -> 0.002845776 | F39: =INDEX(Data!$B$4:$B$74,9) -> 0.58141276 | G39: =INDEX(Data!$C$4:$C$74,9) -> 0.98211109 | H39: =(E40-E38)/2 -> 0.00042675702 | I39: =$B$6*(0.75*(E39+F39))^0.25 -> 4696.1602 | J39: =$B$6*(0.75*(E39+2/3))^0.25 -> 4858.8255 | K39: =2*hP*cL^2/($B$7*0.000000001)^5/(EXP(hP*cL/($B$7*0.000000001*kB*I39))-1) -> 8.3349638e+12 | M39: 0.95 | N39: =SUMPRODUCT($K$31:$K$101,EXP(-$E$31:$E$101/M39)/M39,$H$31:$H$101) -> 3.3246423e+13 | O39: =N39/N40 -> 0.96547475 | P39: =(2+3*M39)/5 -> 0.97 | Q39: =INDEX(Data!$G$4:$G$24,MATCH(ROUND(M39*20,0)/20,Data!$E$4:$E$24,1)) -> 0.96955159 | S39: 35.457 | T39: =2*PI()*SUMPRODUCT(2*hP*cL^2/(S39*0.000000001)^5/(EXP(hP*cL/(S39*0.000000001*kB*$I$31:$I$101))-1),$G$31:$G$101,$H$31:$H$101) -> 0.27775411 | U39: =(S40-S38)/2*0.000000001 -> 2.54e-09 | V39: =PI()*2*hP*cL^2/(S39*0.000000001)^5/(EXP(hP*cL/(S39*0.000000001*kB*$B$6))-1) -> 1.9632486e-09
E40: =INDEX(Data!$A$4:$A$74,10) -> 0.0033043537 | F40: =INDEX(Data!$B$4:$B$74,10) -> 0.58193314 | G40: =INDEX(Data!$C$4:$C$74,10) -> 0.97972135 | H40: =(E41-E39)/2 -> 0.00049552605 | I40: =$B$6*(0.75*(E40+F40))^0.25 -> 4698.1261 | J40: =$B$6*(0.75*(E40+2/3))^0.25 -> 4859.6573 | K40: =2*hP*cL^2/($B$7*0.000000001)^5/(EXP(hP*cL/($B$7*0.000000001*kB*I40))-1) -> 8.3564093e+12 | M40: 1 | N40: =SUMPRODUCT($K$31:$K$101,EXP(-$E$31:$E$101/M40)/M40,$H$31:$H$101) -> 3.4435311e+13 | O40: =N40/N40 -> 1 | P40: =(2+3*M40)/5 -> 1 | Q40: =INDEX(Data!$G$4:$G$24,MATCH(ROUND(M40*20,0)/20,Data!$E$4:$E$24,1)) -> 1 | S40: 38.088 | T40: =2*PI()*SUMPRODUCT(2*hP*cL^2/(S40*0.000000001)^5/(EXP(hP*cL/(S40*0.000000001*kB*$I$31:$I$101))-1),$G$31:$G$101,$H$31:$H$101) -> 3.6847922 | U40: =(S41-S39)/2*0.000000001 -> 2.7285e-09 | V40: =PI()*2*hP*cL^2/(S40*0.000000001)^5/(EXP(hP*cL/(S40*0.000000001*kB*$B$6))-1) -> 1.7642956e-07
E41: =INDEX(Data!$A$4:$A$74,11) -> 0.0038368281 | F41: =INDEX(Data!$B$4:$B$74,11) -> 0.5825154 | G41: =INDEX(Data!$C$4:$C$74,11) -> 0.9770258 | H41: =(E42-E40)/2 -> 0.00057537674 | I41: =$B$6*(0.75*(E41+F41))^0.25 -> 4700.3617 | J41: =$B$6*(0.75*(E41+2/3))^0.25 -> 4860.6226 | K41: =2*hP*cL^2/($B$7*0.000000001)^5/(EXP(hP*cL/($B$7*0.000000001*kB*I41))-1) -> 8.3808417e+12 | S41: 40.914 | T41: =2*PI()*SUMPRODUCT(2*hP*cL^2/(S41*0.000000001)^5/(EXP(hP*cL/(S41*0.000000001*kB*$I$31:$I$101))-1),$G$31:$G$101,$H$31:$H$101) -> 41.53404 | U41: =(S42-S40)/2*0.000000001 -> 2.9305e-09 | V41: =PI()*2*hP*cL^2/(S41*0.000000001)^5/(EXP(hP*cL/(S41*0.000000001*kB*$B$6))-1) -> 1.1333073e-05
E42: =INDEX(Data!$A$4:$A$74,12) -> 0.0044551071 | F42: =INDEX(Data!$B$4:$B$74,12) -> 0.58316608 | G42: =INDEX(Data!$C$4:$C$74,12) -> 0.9739879 | H42: =(E43-E41)/2 -> 0.00066809484 | I42: =$B$6*(0.75*(E42+F42))^0.25 -> 4702.9028 | J42: =$B$6*(0.75*(E42+2/3))^0.25 -> 4861.7427 | K42: =2*hP*cL^2/($B$7*0.000000001)^5/(EXP(hP*cL/($B$7*0.000000001*kB*I42))-1) -> 8.4086707e+12 | S42: 43.949 | T42: =2*PI()*SUMPRODUCT(2*hP*cL^2/(S42*0.000000001)^5/(EXP(hP*cL/(S42*0.000000001*kB*$I$31:$I$101))-1),$G$31:$G$101,$H$31:$H$101) -> 401.27466 | U42: =(S43-S41)/2*0.000000001 -> 3.148e-09 | V42: =PI()*2*hP*cL^2/(S42*0.000000001)^5/(EXP(hP*cL/(S42*0.000000001*kB*$B$6))-1) -> 0.00053232332
